Workbook

Sheet Préstamos
A1: Valor del activo | C1: 4500000 | D1: =$K$2 -> USD | E1: Personal | F1: 20000 | G1: =$K$2 -> USD | I1: usando activo | J1: 0 | L1: (1 = on) | P1: letusnetwork.com
A2: Porcentaje de préstamo | C2: 0.7 | I2: currency | J2: 1 | K2: =IF(J2=0,"MXN",IF(J2=1,"USD","ERROR")) -> USD | L2: (0 = MXN; 1 = USD) | AH2: log
H3: bitcoin | I3: open index | J3: 6 | L3: (6 = open, 9 = close) | AH3: 0.1.0 | AI3: release
A4: Total de préstamo | C4: =IF(J1=1,C2*C1,F1) -> 20000 | D4: =$K$2 -> USD | I4: close index | J4: 9
A5: Tasa anual | C5: 0.09 | H5: mxn | I5: open index | J5: 3 | K5: mxn | L5: (3 = open, 6 = close)
A6: Períodos: | C6: 60 | I6: close index | J6: 6
A7: Pagos cada: | C7: 30 | D7: días
L8: Préstamos 0.1.0
A9: Inicio | C9: 44301 | E9: Hoy | F9: =G9/(24*60*60)+DATE(1970,1,1) -> 46005 | G9: =INDEX_BTCUSD_1D!P1 -> 1765670400 | L9: autor: | M9: bc1quvrkgsnjxgdyn0cazc3ed4zllsdnpu38lyfg9a
E10: Pagos pendientes | F10: =C6-COUNTIF(C17:C136,"<"&$F$9) -> 4 | G10: =I17*F10 -> -1660.6684 | L10: last update: | M10: 888659 | N10: 9fbc
D12: activo | R12: pasivo
D13: inicio de período | I13: fin de período | R13: inicio de período | U13: fin de período
D14: balance | F14: tipo de cambio | G14: valor | H14: total | I14: pago | J14: compra/venta | K14: total | L14: balance | N14: tipo de cambio | O14: valor | P14: total | R14: balance | U14: pagos | Y14: balance
A15: p | B15: unix time | C15: fecha | D15: =$K$2 -> USD | E15: =$H$3 -> bitcoin | F15: =_xlfn.CONCAT($H$3,"/",$K$2) -> bitcoin/USD | G15: =$K$2 -> USD | H15: =$K$2 -> USD | I15: =$K$2 -> USD | J15: =$H$3 -> bitcoin | K15: =$K$2 -> USD | L15: =$K$2 -> USD | M15: =$H$3 -> bitcoin | N15: =_xlfn.CONCAT($H$3,"/",$K$2) -> bitcoin/USD | O15: =$K$2 -> USD | P15: =$K$2 -> USD | Q15: ROI | R15: =$K$2 -> USD | S15: interés | T15: total | U15: restantes | V15: =$K$2 -> USD | W15: a interés | X15: a capital | Y15: =$K$2 -> USD | Z15: interés | AA15: total
A16: 0 | B16: =(C16-DATE(1970,1,1))*(24*60*60) -> 1618444800 | C16: =C9 -> 44301 | D16: =C4 -> 20000 | E16: 0 | F16: =IF($J$2=1,IFERROR(VLOOKUP(B16,INDEX_BTCUSD_1D!$A$1:$I$5543,$J$3,0),0),IFERROR(VLOOKUP(B16,INDEX_BTCUSD_1D!$A$1:$I$5543,$J$3,0),0)*IFERROR(VLOOKUP(B16,FX_USDMXN_1D!$A$1:$F$4614,$J$5),0)) -> 62966.465 | G16: =E16*F16 -> 0 | H16: =D16+G16 -> 20000 | I16: 0 | J16: 0 | K16: =-J16*F16 -> 0 | L16: =D16+I16+K16 -> 20000 | M16: =E16+J16 -> 0 | N16: =IF($J$2=1,IFERROR(VLOOKUP(B16,INDEX_BTCUSD_1D!$A$1:$I$5543,$J$4,0),0),IFERROR(VLOOKUP(B16,INDEX_BTCUSD_1D!$A$1:$I$5543,$J$4,0),0)*IFERROR(VLOOKUP(B16,FX_USDMXN_1D!$A$1:$F$4614,$J$6),0)) -> 63237.223 | O16: =M16*N16 -> 0 | P16: =L16+O16 -> 20000 | Q16: =IF(AND(ISNUMBER(A16)=1,C16<$F$9),(P16+R16)/$C$4,"") -> 0 | R16: =-C4 -> -20000 | S16: =CUMIPMT($C$5/12,$C$6,$C$4,1,$C$6,0) -> -4910.0263 | T16: =R16+S16 -> -24910.026 | U16: =C6 -> 60 | V16: 0 | W16: 0 | X16: 0 | Y16: =R16+X16 -> -20000 | Z16: =S16+W16 -> -4910.0263 | AA16: =Y16+Z16 -> -24910.026
A17: =IF(A16<$C$6,A16+1,"") -> 1 | B17: =(C17-DATE(1970,1,1))*(24*60*60) -> 1621036800 | C17: =C16+$C$7 -> 44331 | D17: =L16 -> 20000 | E17: =M16 -> 0 | F17: =IF($J$2=1,IFERROR(VLOOKUP(B17,INDEX_BTCUSD_1D!$A$1:$I$5543,$J$3,0),0),IFERROR(VLOOKUP(B17,INDEX_BTCUSD_1D!$A$1:$I$5543,$J$3,0),0)*IFERROR(VLOOKUP(B17,FX_USDMXN_1D!$A$1:$F$4614,$J$5),0)) -> 49895.628 | G17: =E17*F17 -> 0 | H17: =D17+G17 -> 20000 | I17: =-V17 -> -415.1671 | J17: =(-I17)/F17 -> 0.0083207112 | K17: =-J17*F17 -> -415.1671 | L17: =D17+I17+K17 -> 19169.666 | M17: =E17+J17 -> 0.0083207112 | N17: =IF($J$2=1,IFERROR(VLOOKUP(B17,INDEX_BTCUSD_1D!$A$1:$I$5543,$J$4,0),0),IFERROR(VLOOKUP(B17,INDEX_BTCUSD_1D!$A$1:$I$5543,$J$4,0),0)*IFERROR(VLOOKUP(B17,FX_USDMXN_1D!$A$1:$F$4614,$J$6),0)) -> 46756.408 | O17: =M17*N17 -> 389.04656 | P17: =L17+O17 -> 19558.712 | Q17: =IF(AND(ISNUMBER(A17)=1,C17<$F$9),(P17+R17)/$C$4,"") -> -0.022064382 | R17: =Y16 -> -20000 | S17: =Z16 -> -4910.0263 | T17: =AA16 -> -24910.026 | U17: =U16-1 -> 59 | V17: =IF(U17>=0,-PMT($C$5/12,$C$6,$C$4,,0)) -> 415.1671 | W17: =IF(U17>=0,-CUMIPMT($C$5/12,$C$6,$C$4,A17,A17,0)) -> 150 | X17: =V17-W17 -> 265.1671 | Y17: =R17+X17 -> -19734.833 | Z17: =S17+W17 -> -4760.0263 | AA17: =Y17+Z17 -> -24494.859
A18: =IF(A17<$C$6,A17+1,"") -> 2 | B18: =(C18-DATE(1970,1,1))*(24*60*60) -> 1623628800 | C18: =C17+$C$7 -> 44361 | D18: =L17 -> 19169.666 | E18: =M17 -> 0.0083207112 | F18: =IF($J$2=1,IFERROR(VLOOKUP(B18,INDEX_BTCUSD_1D!$A$1:$I$5543,$J$3,0),0),IFERROR(VLOOKUP(B18,INDEX_BTCUSD_1D!$A$1:$I$5543,$J$3,0),0)*IFERROR(VLOOKUP(B18,FX_USDMXN_1D!$A$1:$F$4614,$J$5),0)) -> 39026.76 | G18: =E18*F18 -> 324.7304 | H18: =D18+G18 -> 19494.396 | I18: =-V18 -> -415.1671 | J18: =(-I18)/F18 -> 0.010638011 | K18: =-J18*F18 -> -415.1671 | L18: =D18+I18+K18 -> 18339.332 | M18: =E18+J18 -> 0.018958722 | N18: =IF($J$2=1,IFERROR(VLOOKUP(B18,INDEX_BTCUSD_1D!$A$1:$I$5543,$J$4,0),0),IFERROR(VLOOKUP(B18,INDEX_BTCUSD_1D!$A$1:$I$5543,$J$4,0),0)*IFERROR(VLOOKUP(B18,FX_USDMXN_1D!$A$1:$F$4614,$J$6),0)) -> 40534.765 | O18: =M18*N18 -> 768.48735 | P18: =L18+O18 -> 19107.819 | Q18: =IF(AND(ISNUMBER(A18)=1,C18<$F$9),(P18+R18)/$C$4,"") -> -0.031350698 | R18: =Y17 -> -19734.833 | S18: =Z17 -> -4760.0263 | T18: =AA17 -> -24494.859 | U18: =U17-1 -> 58 | V18: =IF(U18>=0,-PMT($C$5/12,$C$6,$C$4,,0)) -> 415.1671 | W18: =IF(U18>=0,-CUMIPMT($C$5/12,$C$6,$C$4,A18,A18,0)) -> 148.01125 | X18: =V18-W18 -> 267.15586 | Y18: =R18+X18 -> -19467.677 | Z18: =S18+W18 -> -4612.015 | AA18: =Y18+Z18 -> -24079.692
A19: =IF(A18<$C$6,A18+1,"") -> 3 | B19: =(C19-DATE(1970,1,1))*(24*60*60) -> 1626220800 | C19: =C18+$C$7 -> 44391 | D19: =L18 -> 18339.332 | E19: =M18 -> 0.018958722 | F19: =IF($J$2=1,IFERROR(VLOOKUP(B19,INDEX_BTCUSD_1D!$A$1:$I$5543,$J$3,0),0),IFERROR(VLOOKUP(B19,INDEX_BTCUSD_1D!$A$1:$I$5543,$J$3,0),0)*IFERROR(VLOOKUP(B19,FX_USDMXN_1D!$A$1:$F$4614,$J$5),0)) -> 32733.18 | G19: =E19*F19 -> 620.57927 | H19: =D19+G19 -> 18959.911 | I19: =-V19 -> -415.1671 | J19: =(-I19)/F19 -> 0.012683372 | K19: =-J19*F19 -> -415.1671 | L19: =D19+I19+K19 -> 17508.997 | M19: =E19+J19 -> 0.031642094 | N19: =IF($J$2=1,IFERROR(VLOOKUP(B19,INDEX_BTCUSD_1D!$A$1:$I$5543,$J$4,0),0),IFERROR(VLOOKUP(B19,INDEX_BTCUSD_1D!$A$1:$I$5543,$J$4,0),0)*IFERROR(VLOOKUP(B19,FX_USDMXN_1D!$A$1:$F$4614,$J$6),0)) -> 32819.077 | O19: =M19*N19 -> 1038.4643 | P19: =L19+O19 -> 18547.462 | Q19: =IF(AND(ISNUMBER(A19)=1,C19<$F$9),(P19+R19)/$C$4,"") -> -0.046010766 | R19: =Y18 -> -19467.677 | S19: =Z18 -> -4612.015 | T19: =AA18 -> -24079.692 | U19: =U18-1 -> 57 | V19: =IF(U19>=0,-PMT($C$5/12,$C$6,$C$4,,0)) -> 415.1671 | W19: =IF(U19>=0,-CUMIPMT($C$5/12,$C$6,$C$4,A19,A19,0)) -> 146.00758 | X19: =V19-W19 -> 269.15953 | Y19: =R19+X19 -> -19198.518 | Z19: =S19+W19 -> -4466.0074 | AA19: =Y19+Z19 -> -23664.525
A20: =IF(A19<$C$6,A19+1,"") -> 4 | B20: =(C20-DATE(1970,1,1))*(24*60*60) -> 1628812800 | C20: =C19+$C$7 -> 44421 | D20: =L19 -> 17508.997 | E20: =M19 -> 0.031642094 | F20: =IF($J$2=1,IFERROR(VLOOKUP(B20,INDEX_BTCUSD_1D!$A$1:$I$5543,$J$3,0),0),IFERROR(VLOOKUP(B20,INDEX_BTCUSD_1D!$A$1:$I$5543,$J$3,0),0)*IFERROR(VLOOKUP(B20,FX_USDMXN_1D!$A$1:$F$4614,$J$5),0)) -> 44415.9 | G20: =E20*F20 -> 1405.4121 | H20: =D20+G20 -> 18914.409 | I20: =-V20 -> -415.1671 | J20: =(-I20)/F20 -> 0.0093472631 | K20: =-J20*F20 -> -415.1671 | L20: =D20+I20+K20 -> 16678.663 | M20: =E20+J20 -> 0.040989358 | N20: =IF($J$2=1,IFERROR(VLOOKUP(B20,INDEX_BTCUSD_1D!$A$1:$I$5543,$J$4,0),0),IFERROR(VLOOKUP(B20,INDEX_BTCUSD_1D!$A$1:$I$5543,$J$4,0),0)*IFERROR(VLOOKUP(B20,FX_USDMXN_1D!$A$1:$F$4614,$J$6),0)) -> 47838.408 | O20: =M20*N20 -> 1960.8656 | P20: =L20+O20 -> 18639.529 | Q20: =IF(AND(ISNUMBER(A20)=1,C20<$F$9),(P20+R20)/$C$4,"") -> -0.027949438 | R20: =Y19 -> -19198.518 | S20: =Z19 -> -4466.0074 | T20: =AA19 -> -23664.525 | U20: =U19-1 -> 56 | V20: =IF(U20>=0,-PMT($C$5/12,$C$6,$C$4,,0)) -> 415.1671 | W20: =IF(U20>=0,-CUMIPMT($C$5/12,$C$6,$C$4,A20,A20,0)) -> 143.98888 | X20: =V20-W20 -> 271.17822 | Y20: =R20+X20 -> -18927.339 | Z20: =S20+W20 -> -4322.0186 | AA20: =Y20+Z20 -> -23249.358
A21: =IF(A20<$C$6,A20+1,"") -> 5 | B21: =(C21-DATE(1970,1,1))*(24*60*60) -> 1631404800 | C21: =C20+$C$7 -> 44451 | D21: =L20 -> 16678.663 | E21: =M20 -> 0.040989358 | F21: =IF($J$2=1,IFERROR(VLOOKUP(B21,INDEX_BTCUSD_1D!$A$1:$I$5543,$J$3,0),0),IFERROR(VLOOKUP(B21,INDEX_BTCUSD_1D!$A$1:$I$5543,$J$3,0),0)*IFERROR(VLOOKUP(B21,FX_USDMXN_1D!$A$1:$F$4614,$J$5),0)) -> 45166.228 | G21: =E21*F21 -> 1851.3346 | H21: =D21+G21 -> 18529.998 | I21: =-V21 -> -415.1671 | J21: =(-I21)/F21 -> 0.009191981 | K21: =-J21*F21 -> -415.1671 | L21: =D21+I21+K21 -> 15848.329 | M21: =E21+J21 -> 0.050181339 | N21: =IF($J$2=1,IFERROR(VLOOKUP(B21,INDEX_BTCUSD_1D!$A$1:$I$5543,$J$4,0),0),IFERROR(VLOOKUP(B21,INDEX_BTCUSD_1D!$A$1:$I$5543,$J$4,0),0)*IFERROR(VLOOKUP(B21,FX_USDMXN_1D!$A$1:$F$4614,$J$6),0)) -> 46038.893 | O21: =M21*N21 -> 2310.2932 | P21: =L21+O21 -> 18158.622 | Q21: =IF(AND(ISNUMBER(A21)=1,C21<$F$9),(P21+R21)/$C$4,"") -> -0.038435854 | R21: =Y20 -> -18927.339 | S21: =Z20 -> -4322.0186 | T21: =AA20 -> -23249.358 | U21: =U20-1 -> 55 | V21: =IF(U21>=0,-PMT($C$5/12,$C$6,$C$4,,0)) -> 415.1671 | W21: =IF(U21>=0,-CUMIPMT($C$5/12,$C$6,$C$4,A21,A21,0)) -> 141.95504 | X21: =V21-W21 -> 273.21206 | Y21: =R21+X21 -> -18654.127 | Z21: =S21+W21 -> -4180.0635 | AA21: =Y21+Z21 -> -22834.191
A22: =IF(A21<$C$6,A21+1,"") -> 6 | B22: =(C22-DATE(1970,1,1))*(24*60*60) -> 1633996800 | C22: =C21+$C$7 -> 44481 | D22: =L21 -> 15848.329 | E22: =M21 -> 0.050181339 | F22: =IF($J$2=1,IFERROR(VLOOKUP(B22,INDEX_BTCUSD_1D!$A$1:$I$5543,$J$3,0),0),IFERROR(VLOOKUP(B22,INDEX_BTCUSD_1D!$A$1:$I$5543,$J$3,0),0)*IFERROR(VLOOKUP(B22,FX_USDMXN_1D!$A$1:$F$4614,$J$5),0)) -> 57487.287 | G22: =E22*F22 -> 2884.789 | H22: =D22+G22 -> 18733.118 | I22: =-V22 -> -415.1671 | J22: =(-I22)/F22 -> 0.0072218941 | K22: =-J22*F22 -> -415.1671 | L22: =D22+I22+K22 -> 15017.995 | M22: =E22+J22 -> 0.057403233 | N22: =IF($J$2=1,IFERROR(VLOOKUP(B22,INDEX_BTCUSD_1D!$A$1:$I$5543,$J$4,0),0),IFERROR(VLOOKUP(B22,INDEX_BTCUSD_1D!$A$1:$I$5543,$J$4,0),0)*IFERROR(VLOOKUP(B22,FX_USDMXN_1D!$A$1:$F$4614,$J$6),0)) -> 56007.442 | O22: =M22*N22 -> 3215.0083 | P22: =L22+O22 -> 18233.003 | Q22: =IF(AND(ISNUMBER(A22)=1,C22<$F$9),(P22+R22)/$C$4,"") -> -0.021056211 | R22: =Y21 -> -18654.127 | S22: =Z21 -> -4180.0635 | T22: =AA21 -> -22834.191 | U22: =U21-1 -> 54 | V22: =IF(U22>=0,-PMT($C$5/12,$C$6,$C$4,,0)) -> 415.1671 | W22: =IF(U22>=0,-CUMIPMT($C$5/12,$C$6,$C$4,A22,A22,0)) -> 139.90595 | X22: =V22-W22 -> 275.26115 | Y22: =R22+X22 -> -18378.866 | Z22: =S22+W22 -> -4040.1576 | AA22: =Y22+Z22 -> -22419.024
A23: =IF(A22<$C$6,A22+1,"") -> 7 | B23: =(C23-DATE(1970,1,1))*(24*60*60) -> 1636588800 | C23: =C22+$C$7 -> 44511 | D23: =L22 -> 15017.995 | E23: =M22 -> 0.057403233 | F23: =IF($J$2=1,IFERROR(VLOOKUP(B23,INDEX_BTCUSD_1D!$A$1:$I$5543,$J$3,0),0),IFERROR(VLOOKUP(B23,INDEX_BTCUSD_1D!$A$1:$I$5543,$J$3,0),0)*IFERROR(VLOOKUP(B23,FX_USDMXN_1D!$A$1:$F$4614,$J$5),0)) -> 64929.27 | G23: =E23*F23 -> 3727.15 | H23: =D23+G23 -> 18745.145 | I23: =-V23 -> -415.1671 | J23: =(-I23)/F23 -> 0.006394144 | K23: =-J23*F23 -> -415.1671 | L23: =D23+I23+K23 -> 14187.661 | M23: =E23+J23 -> 0.063797377 | N23: =IF($J$2=1,IFERROR(VLOOKUP(B23,INDEX_BTCUSD_1D!$A$1:$I$5543,$J$4,0),0),IFERROR(VLOOKUP(B23,INDEX_BTCUSD_1D!$A$1:$I$5543,$J$4,0),0)*IFERROR(VLOOKUP(B23,FX_USDMXN_1D!$A$1:$F$4614,$J$6),0)) -> 64822.07 | O23: =M23*N23 -> 4135.478 | P23: =L23+O23 -> 18323.139 | Q23: =IF(AND(ISNUMBER(A23)=1,C23<$F$9),(P23+R23)/$C$4,"") -> -0.0027863762 | R23: =Y22 -> -18378.866 | S23: =Z22 -> -4040.1576 | T23: =AA22 -> -22419.024 | U23: =U22-1 -> 53 | V23: =IF(U23>=0,-PMT($C$5/12,$C$6,$C$4,,0)) -> 415.1671 | W23: =IF(U23>=0,-CUMIPMT($C$5/12,$C$6,$C$4,A23,A23,0)) -> 137.8415 | X23: =V23-W23 -> 277.32561 | Y23: =R23+X23 -> -18101.54 | Z23: =S23+W23 -> -3902.3161 | AA23: =Y23+Z23 -> -22003.857
A24: =IF(A23<$C$6,A23+1,"") -> 8 | B24: =(C24-DATE(1970,1,1))*(24*60*60) -> 1639180800 | C24: =C23+$C$7 -> 44541 | D24: =L23 -> 14187.661 | E24: =M23 -> 0.063797377 | F24: =IF($J$2=1,IFERROR(VLOOKUP(B24,INDEX_BTCUSD_1D!$A$1:$I$5543,$J$3,0),0),IFERROR(VLOOKUP(B24,INDEX_BTCUSD_1D!$A$1:$I$5543,$J$3,0),0)*IFERROR(VLOOKUP(B24,FX_USDMXN_1D!$A$1:$F$4614,$J$5),0)) -> 47492.5 | G24: =E24*F24 -> 3029.8969 | H24: =D24+G24 -> 17217.557 | I24: =-V24 -> -415.1671 | J24: =(-I24)/F24 -> 0.0087417404 | K24: =-J24*F24 -> -415.1671 | L24: =D24+I24+K24 -> 13357.326 | M24: =E24+J24 -> 0.072539117 | N24: =IF($J$2=1,IFERROR(VLOOKUP(B24,INDEX_BTCUSD_1D!$A$1:$I$5543,$J$4,0),0),IFERROR(VLOOKUP(B24,INDEX_BTCUSD_1D!$A$1:$I$5543,$J$4,0),0)*IFERROR(VLOOKUP(B24,FX_USDMXN_1D!$A$1:$F$4614,$J$6),0)) -> 49369.71 | O24: =M24*N24 -> 3581.2352 | P24: =L24+O24 -> 16938.562 | Q24: =IF(AND(ISNUMBER(A24)=1,C24<$F$9),(P24+R24)/$C$4,"") -> -0.058148948 | R24: =Y23 -> -18101.54 | S24: =Z23 -> -3902.3161 | T24: =AA23 -> -22003.857 | U24: =U23-1 -> 52 | V24: =IF(U24>=0,-PMT($C$5/12,$C$6,$C$4,,0)) -> 415.1671 | W24: =IF(U24>=0,-CUMIPMT($C$5/12,$C$6,$C$4,A24,A24,0)) -> 135.76155 | X24: =V24-W24 -> 279.40555 | Y24: =R24+X24 -> -17822.135 | Z24: =S24+W24 -> -3766.5545 | AA24: =Y24+Z24 -> -21588.689
A25: =IF(A24<$C$6,A24+1,"") -> 9 | B25: =(C25-DATE(1970,1,1))*(24*60*60) -> 1641772800 | C25: =C24+$C$7 -> 44571 | D25: =L24 -> 13357.326 | E25: =M24 -> 0.072539117 | F25: =IF($J$2=1,IFERROR(VLOOKUP(B25,INDEX_BTCUSD_1D!$A$1:$I$5543,$J$3,0),0),IFERROR(VLOOKUP(B25,INDEX_BTCUSD_1D!$A$1:$I$5543,$J$3,0),0)*IFERROR(VLOOKUP(B25,FX_USDMXN_1D!$A$1:$F$4614,$J$5),0)) -> 41883.5 | G25: =E25*F25 -> 3038.1921 | H25: =D25+G25 -> 16395.518 | I25: =-V25 -> -415.1671 | J25: =(-I25)/F25 -> 0.0099124262 | K25: =-J25*F25 -> -415.1671 | L25: =D25+I25+K25 -> 12526.992 | M25: =E25+J25 -> 0.082451543 | N25: =IF($J$2=1,IFERROR(VLOOKUP(B25,INDEX_BTCUSD_1D!$A$1:$I$5543,$J$4,0),0),IFERROR(VLOOKUP(B25,INDEX_BTCUSD_1D!$A$1:$I$5543,$J$4,0),0)*IFERROR(VLOOKUP(B25,FX_USDMXN_1D!$A$1:$F$4614,$J$6),0)) -> 41837.29 | O25: =M25*N25 -> 3449.5491 | P25: =L25+O25 -> 15976.541 | Q25: =IF(AND(ISNUMBER(A25)=1,C25<$F$9),(P25+R25)/$C$4,"") -> -0.092279684 | R25: =Y24 -> -17822.135 | S25: =Z24 -> -3766.5545 | T25: =AA24 -> -21588.689 | U25: =U24-1 -> 51 | V25: =IF(U25>=0,-PMT($C$5/12,$C$6,$C$4,,0)) -> 415.1671 | W25: =IF(U25>=0,-CUMIPMT($C$5/12,$C$6,$C$4,A25,A25,0)) -> 133.66601 | X25: =V25-W25 -> 281.50109 | Y25: =R25+X25 -> -17540.634 | Z25: =S25+W25 -> -3632.8885 | AA25: =Y25+Z25 -> -21173.522
A26: =IF(A25<$C$6,A25+1,"") -> 10 | B26: =(C26-DATE(1970,1,1))*(24*60*60) -> 1644364800 | C26: =C25+$C$7 -> 44601 | D26: =L25 -> 12526.992 | E26: =M25 -> 0.082451543 | F26: =IF($J$2=1,IFERROR(VLOOKUP(B26,INDEX_BTCUSD_1D!$A$1:$I$5543,$J$3,0),0),IFERROR(VLOOKUP(B26,INDEX_BTCUSD_1D!$A$1:$I$5543,$J$3,0),0)*IFERROR(VLOOKUP(B26,FX_USDMXN_1D!$A$1:$F$4614,$J$5),0)) -> 44089.95 | G26: =E26*F26 -> 3635.2844 | H26: =D26+G26 -> 16162.277 | I26: =-V26 -> -415.1671 | J26: =(-I26)/F26 -> 0.009416366 | K26: =-J26*F26 -> -415.1671 | L26: =D26+I26+K26 -> 11696.658 | M26: =E26+J26 -> 0.091867909 | N26: =IF($J$2=1,IFERROR(VLOOKUP(B26,INDEX_BTCUSD_1D!$A$1:$I$5543,$J$4,0),0),IFERROR(VLOOKUP(B26,INDEX_BTCUSD_1D!$A$1:$I$5543,$J$4,0),0)*IFERROR(VLOOKUP(B26,FX_USDMXN_1D!$A$1:$F$4614,$J$6),0)) -> 44420.56 | O26: =M26*N26 -> 4080.824 | P26: =L26+O26 -> 15777.482 | Q26: =IF(AND(ISNUMBER(A26)=1,C26<$F$9),(P26+R26)/$C$4,"") -> -0.088157597 | R26: =Y25 -> -17540.634 | S26: =Z25 -> -3632.8885 | T26: =AA25 -> -21173.522 | U26: =U25-1 -> 50 | V26: =IF(U26>=0,-PMT($C$5/12,$C$6,$C$4,,0)) -> 415.1671 | W26: =IF(U26>=0,-CUMIPMT($C$5/12,$C$6,$C$4,A26,A26,0)) -> 131.55475 | X26: =V26-W26 -> 283.61235 | Y26: =R26+X26 -> -17257.021 | Z26: =S26+W26 -> -3501.3338 | AA26: =Y26+Z26 -> -20758.355
A27: =IF(A26<$C$6,A26+1,"") -> 11 | B27: =(C27-DATE(1970,1,1))*(24*60*60) -> 1646956800 | C27: =C26+$C$7 -> 44631 | D27: =L26 -> 11696.658 | E27: =M26 -> 0.091867909 | F27: =IF($J$2=1,IFERROR(VLOOKUP(B27,INDEX_BTCUSD_1D!$A$1:$I$5543,$J$3,0),0),IFERROR(VLOOKUP(B27,INDEX_BTCUSD_1D!$A$1:$I$5543,$J$3,0),0)*IFERROR(VLOOKUP(B27,FX_USDMXN_1D!$A$1:$F$4614,$J$5),0)) -> 39433.9 | G27: =E27*F27 -> 3622.7099 | H27: =D27+G27 -> 15319.368 | I27: =-V27 -> -415.1671 | J27: =(-I27)/F27 -> 0.010528178 | K27: =-J27*F27 -> -415.1671 | L27: =D27+I27+K27 -> 10866.324 | M27: =E27+J27 -> 0.10239609 | N27: =IF($J$2=1,IFERROR(VLOOKUP(B27,INDEX_BTCUSD_1D!$A$1:$I$5543,$J$4,0),0),IFERROR(VLOOKUP(B27,INDEX_BTCUSD_1D!$A$1:$I$5543,$J$4,0),0)*IFERROR(VLOOKUP(B27,FX_USDMXN_1D!$A$1:$F$4614,$J$6),0)) -> 38735.35 | O27: =M27*N27 -> 3966.3483 | P27: =L27+O27 -> 14832.672 | Q27: =IF(AND(ISNUMBER(A27)=1,C27<$F$9),(P27+R27)/$C$4,"") -> -0.12121748 | R27: =Y26 -> -17257.021 | S27: =Z26 -> -3501.3338 | T27: =AA26 -> -20758.355 | U27: =U26-1 -> 49 | V27: =IF(U27>=0,-PMT($C$5/12,$C$6,$C$4,,0)) -> 415.1671 | W27: =IF(U27>=0,-CUMIPMT($C$5/12,$C$6,$C$4,A27,A27,0)) -> 129.42766 | X27: =V27-W27 -> 285.73944 | Y27: =R27+X27 -> -16971.282 | Z27: =S27+W27 -> -3371.9061 | AA27: =Y27+Z27 -> -20343.188
A28: =IF(A27<$C$6,A27+1,"") -> 12 | B28: =(C28-DATE(1970,1,1))*(24*60*60) -> 1649548800 | C28: =C27+$C$7 -> 44661 | D28: =L27 -> 10866.324 | E28: =M27 -> 0.10239609 | F28: =IF($J$2=1,IFERROR(VLOOKUP(B28,INDEX_BTCUSD_1D!$A$1:$I$5543,$J$3,0),0),IFERROR(VLOOKUP(B28,INDEX_BTCUSD_1D!$A$1:$I$5543,$J$3,0),0)*IFERROR(VLOOKUP(B28,FX_USDMXN_1D!$A$1:$F$4614,$J$5),0)) -> 42774.7 | G28: =E28*F28 -> 4379.9619 | H28: =D28+G28 -> 15246.286 | I28: =-V28 -> -415.1671 | J28: =(-I28)/F28 -> 0.0097059034 | K28: =-J28*F28 -> -415.1671 | L28: =D28+I28+K28 -> 10035.989 | M28: =E28+J28 -> 0.11210199 | N28: =IF($J$2=1,IFERROR(VLOOKUP(B28,INDEX_BTCUSD_1D!$A$1:$I$5543,$J$4,0),0),IFERROR(VLOOKUP(B28,INDEX_BTCUSD_1D!$A$1:$I$5543,$J$4,0),0)*IFERROR(VLOOKUP(B28,FX_USDMXN_1D!$A$1:$F$4614,$J$6),0)) -> 42155.88 | O28: =M28*N28 -> 4725.758 | P28: =L28+O28 -> 14761.748 | Q28: =IF(AND(ISNUMBER(A28)=1,C28<$F$9),(P28+R28)/$C$4,"") -> -0.11047672 | R28: =Y27 -> -16971.282 | S28: =Z27 -> -3371.9061 | T28: =AA27 -> -20343.188 | U28: =U27-1 -> 48 | V28: =IF(U28>=0,-PMT($C$5/12,$C$6,$C$4,,0)) -> 415.1671 | W28: =IF(U28>=0,-CUMIPMT($C$5/12,$C$6,$C$4,A28,A28,0)) -> 127.28462 | X28: =V28-W28 -> 287.88249 | Y28: =R28+X28 -> -16683.4 | Z28: =S28+W28 -> -3244.6215 | AA28: =Y28+Z28 -> -19928.021
... A40: =IF(A39<$C$6,A39+1,"") -> 24 | B40: =(C40-DATE(1970,1,1))*(24*60*60) -> 1680652800 | C40: =C39+$C$7 -> 45021 | D40: =L39 -> 902.31319 | E40: =M39 -> 0.32452651 | F40: =IF($J$2=1,IFERROR(VLOOKUP(B40,INDEX_BTCUSD_1D!$A$1:$I$5543,$J$3,0),0),IFERROR(VLOOKUP(B40,INDEX_BTCUSD_1D!$A$1:$I$5543,$J$3,0),0)*IFERROR(VLOOKUP(B40,FX_USDMXN_1D!$A$1:$F$4614,$J$5),0)) -> 28176.04 | G40: =E40*F40 -> 9143.872 | H40: =D40+G40 -> 10046.185 | I40: =-V40 -> -415.1671 | J40: =(-I40)/F40 -> 0.014734757 | K40: =-J40*F40 -> -415.1671 | L40: =D40+I40+K40 -> 71.978983 | M40: =E40+J40 -> 0.33926127 | N40: =IF($J$2=1,IFERROR(VLOOKUP(B40,INDEX_BTCUSD_1D!$A$1:$I$5543,$J$4,0),0),IFERROR(VLOOKUP(B40,INDEX_BTCUSD_1D!$A$1:$I$5543,$J$4,0),0)*IFERROR(VLOOKUP(B40,FX_USDMXN_1D!$A$1:$F$4614,$J$6),0)) -> 28180.65 | O40: =M40*N40 -> 9560.6031 | P40: =L40+O40 -> 9632.5821 | Q40: =IF(AND(ISNUMBER(A40)=1,C40<$F$9),(P40+R40)/$C$4,"") -> -0.18689924 | R40: =Y39 -> -13370.567 | S40: =Z39 -> -1990.6159 | T40: =AA39 -> -15361.183 | U40: =U39-1 -> 36 | V40: =IF(U40>=0,-PMT($C$5/12,$C$6,$C$4,,0)) -> 415.1671 | W40: =IF(U40>=0,-CUMIPMT($C$5/12,$C$6,$C$4,A40,A40,0)) -> 100.27925 | X40: =V40-W40 -> 314.88785 | Y40: =R40+X40 -> -13055.679 | Z40: =S40+W40 -> -1890.3367 | AA40: =Y40+Z40 -> -14946.016
A41: =IF(A40<$C$6,A40+1,"") -> 25 | B41: =(C41-DATE(1970,1,1))*(24*60*60) -> 1683244800 | C41: =C40+$C$7 -> 45051 | D41: =L40 -> 71.978983 | E41: =M40 -> 0.33926127 | F41: =IF($J$2=1,IFERROR(VLOOKUP(B41,INDEX_BTCUSD_1D!$A$1:$I$5543,$J$3,0),0),IFERROR(VLOOKUP(B41,INDEX_BTCUSD_1D!$A$1:$I$5543,$J$3,0),0)*IFERROR(VLOOKUP(B41,FX_USDMXN_1D!$A$1:$F$4614,$J$5),0)) -> 28872.99 | G41: =E41*F41 -> 9795.4872 | H41: =D41+G41 -> 9867.4662 | I41: =-V41 -> -415.1671 | J41: 0 | K41: =-J41*F41 -> 0 | L41: =D41+I41+K41 -> -343.18812 | M41: =E41+J41 -> 0.33926127 | N41: =IF($J$2=1,IFERROR(VLOOKUP(B41,INDEX_BTCUSD_1D!$A$1:$I$5543,$J$4,0),0),IFERROR(VLOOKUP(B41,INDEX_BTCUSD_1D!$A$1:$I$5543,$J$4,0),0)*IFERROR(VLOOKUP(B41,FX_USDMXN_1D!$A$1:$F$4614,$J$6),0)) -> 29554.64 | O41: =M41*N41 -> 10026.745 | P41: =L41+O41 -> 9683.5566 | Q41: =IF(AND(ISNUMBER(A41)=1,C41<$F$9),(P41+R41)/$C$4,"") -> -0.16860613 | R41: =Y40 -> -13055.679 | S41: =Z40 -> -1890.3367 | T41: =AA40 -> -14946.016 | U41: =U40-1 -> 35 | V41: =IF(U41>=0,-PMT($C$5/12,$C$6,$C$4,,0)) -> 415.1671 | W41: =IF(U41>=0,-CUMIPMT($C$5/12,$C$6,$C$4,A41,A41,0)) -> 97.917593 | X41: =V41-W41 -> 317.24951 | Y41: =R41+X41 -> -12738.43 | Z41: =S41+W41 -> -1792.4191 | AA41: =Y41+Z41 -> -14530.849
A42: =IF(A41<$C$6,A41+1,"") -> 26 | B42: =(C42-DATE(1970,1,1))*(24*60*60) -> 1685836800 | C42: =C41+$C$7 -> 45081 | D42: =L41 -> -343.18812 | E42: =M41 -> 0.33926127 | F42: =IF($J$2=1,IFERROR(VLOOKUP(B42,INDEX_BTCUSD_1D!$A$1:$I$5543,$J$3,0),0),IFERROR(VLOOKUP(B42,INDEX_BTCUSD_1D!$A$1:$I$5543,$J$3,0),0)*IFERROR(VLOOKUP(B42,FX_USDMXN_1D!$A$1:$F$4614,$J$5),0)) -> 27074.82 | G42: =E42*F42 -> 9185.4378 | H42: =D42+G42 -> 8842.2497 | I42: =-V42 -> -415.1671 | J42: 0 | K42: =-J42*F42 -> 0 | L42: =D42+I42+K42 -> -758.35523 | M42: =E42+J42 -> 0.33926127 | N42: =IF($J$2=1,IFERROR(VLOOKUP(B42,INDEX_BTCUSD_1D!$A$1:$I$5543,$J$4,0),0),IFERROR(VLOOKUP(B42,INDEX_BTCUSD_1D!$A$1:$I$5543,$J$4,0),0)*IFERROR(VLOOKUP(B42,FX_USDMXN_1D!$A$1:$F$4614,$J$6),0)) -> 27123.99 | O42: =M42*N42 -> 9202.1193 | P42: =L42+O42 -> 8443.7641 | Q42: =IF(AND(ISNUMBER(A42)=1,C42<$F$9),(P42+R42)/$C$4,"") -> -0.21473328 | R42: =Y41 -> -12738.43 | S42: =Z41 -> -1792.4191 | T42: =AA41 -> -14530.849 | U42: =U41-1 -> 34 | V42: =IF(U42>=0,-PMT($C$5/12,$C$6,$C$4,,0)) -> 415.1671 | W42: =IF(U42>=0,-CUMIPMT($C$5/12,$C$6,$C$4,A42,A42,0)) -> 95.538222 | X42: =V42-W42 -> 319.62888 | Y42: =R42+X42 -> -12418.801 | Z42: =S42+W42 -> -1696.8809 | AA42: =Y42+Z42 -> -14115.682
A43: =IF(A42<$C$6,A42+1,"") -> 27 | B43: =(C43-DATE(1970,1,1))*(24*60*60) -> 1688428800 | C43: =C42+$C$7 -> 45111 | D43: =L42 -> -758.35523 | E43: =M42 -> 0.33926127 | F43: =IF($J$2=1,IFERROR(VLOOKUP(B43,INDEX_BTCUSD_1D!$A$1:$I$5543,$J$3,0),0),IFERROR(VLOOKUP(B43,INDEX_BTCUSD_1D!$A$1:$I$5543,$J$3,0),0)*IFERROR(VLOOKUP(B43,FX_USDMXN_1D!$A$1:$F$4614,$J$5),0)) -> 31163.68 | G43: =E43*F43 -> 10572.63 | H43: =D43+G43 -> 9814.2744 | I43: =-V43 -> -415.1671 | J43: 0 | K43: =-J43*F43 -> 0 | L43: =D43+I43+K43 -> -1173.5223 | M43: =E43+J43 -> 0.33926127 | N43: =IF($J$2=1,IFERROR(VLOOKUP(B43,INDEX_BTCUSD_1D!$A$1:$I$5543,$J$4,0),0),IFERROR(VLOOKUP(B43,INDEX_BTCUSD_1D!$A$1:$I$5543,$J$4,0),0)*IFERROR(VLOOKUP(B43,FX_USDMXN_1D!$A$1:$F$4614,$J$6),0)) -> 30776.54 | O43: =M43*N43 -> 10441.288 | P43: =L43+O43 -> 9267.7657 | Q43: =IF(AND(ISNUMBER(A43)=1,C43<$F$9),(P43+R43)/$C$4,"") -> -0.15755175 | R43: =Y42 -> -12418.801 | S43: =Z42 -> -1696.8809 | T43: =AA42 -> -14115.682 | U43: =U42-1 -> 33 | V43: =IF(U43>=0,-PMT($C$5/12,$C$6,$C$4,,0)) -> 415.1671 | W43: =IF(U43>=0,-CUMIPMT($C$5/12,$C$6,$C$4,A43,A43,0)) -> 93.141005 | X43: =V43-W43 -> 322.0261 | Y43: =R43+X43 -> -12096.775 | Z43: =S43+W43 -> -1603.7399 | AA43: =Y43+Z43 -> -13700.514
A44: =IF(A43<$C$6,A43+1,"") -> 28 | B44: =(C44-DATE(1970,1,1))*(24*60*60) -> 1691020800 | C44: =C43+$C$7 -> 45141 | D44: =L43 -> -1173.5223 | E44: =M43 -> 0.33926127 | F44: =IF($J$2=1,IFERROR(VLOOKUP(B44,INDEX_BTCUSD_1D!$A$1:$I$5543,$J$3,0),0),IFERROR(VLOOKUP(B44,INDEX_BTCUSD_1D!$A$1:$I$5543,$J$3,0),0)*IFERROR(VLOOKUP(B44,FX_USDMXN_1D!$A$1:$F$4614,$J$5),0)) -> 29170.04 | G44: =E44*F44 -> 9896.2648 | H44: =D44+G44 -> 8722.7425 | I44: =-V44 -> -415.1671 | J44: 0 | K44: =-J44*F44 -> 0 | L44: =D44+I44+K44 -> -1588.6894 | M44: =E44+J44 -> 0.33926127 | N44: =IF($J$2=1,IFERROR(VLOOKUP(B44,INDEX_BTCUSD_1D!$A$1:$I$5543,$J$4,0),0),IFERROR(VLOOKUP(B44,INDEX_BTCUSD_1D!$A$1:$I$5543,$J$4,0),0)*IFERROR(VLOOKUP(B44,FX_USDMXN_1D!$A$1:$F$4614,$J$6),0)) -> 29185.84 | O44: =M44*N44 -> 9901.6251 | P44: =L44+O44 -> 8312.9357 | Q44: =IF(AND(ISNUMBER(A44)=1,C44<$F$9),(P44+R44)/$C$4,"") -> -0.18919194 | R44: =Y43 -> -12096.775 | S44: =Z43 -> -1603.7399 | T44: =AA43 -> -13700.514 | U44: =U43-1 -> 32 | V44: =IF(U44>=0,-PMT($C$5/12,$C$6,$C$4,,0)) -> 415.1671 | W44: =IF(U44>=0,-CUMIPMT($C$5/12,$C$6,$C$4,A44,A44,0)) -> 90.725809 | X44: =V44-W44 -> 324.4413 | Y44: =R44+X44 -> -11772.333 | Z44: =S44+W44 -> -1513.0141 | AA44: =Y44+Z44 -> -13285.347
A45: =IF(A44<$C$6,A44+1,"") -> 29 | B45: =(C45-DATE(1970,1,1))*(24*60*60) -> 1693612800 | C45: =C44+$C$7 -> 45171 | D45: =L44 -> -1588.6894 | E45: =M44 -> 0.33926127 | F45: =IF($J$2=1,IFERROR(VLOOKUP(B45,INDEX_BTCUSD_1D!$A$1:$I$5543,$J$3,0),0),IFERROR(VLOOKUP(B45,INDEX_BTCUSD_1D!$A$1:$I$5543,$J$3,0),0)*IFERROR(VLOOKUP(B45,FX_USDMXN_1D!$A$1:$F$4614,$J$5),0)) -> 25804.98 | G45: =E45*F45 -> 8754.6303 | H45: =D45+G45 -> 7165.9408 | I45: =-V45 -> -415.1671 | J45: 0 | K45: =-J45*F45 -> 0 | L45: =D45+I45+K45 -> -2003.8565 | M45: =E45+J45 -> 0.33926127 | N45: =IF($J$2=1,IFERROR(VLOOKUP(B45,INDEX_BTCUSD_1D!$A$1:$I$5543,$J$4,0),0),IFERROR(VLOOKUP(B45,INDEX_BTCUSD_1D!$A$1:$I$5543,$J$4,0),0)*IFERROR(VLOOKUP(B45,FX_USDMXN_1D!$A$1:$F$4614,$J$6),0)) -> 25869.38 | O45: =M45*N45 -> 8776.4787 | P45: =L45+O45 -> 6772.6222 | Q45: =IF(AND(ISNUMBER(A45)=1,C45<$F$9),(P45+R45)/$C$4,"") -> -0.24998556 | R45: =Y44 -> -11772.333 | S45: =Z44 -> -1513.0141 | T45: =AA44 -> -13285.347 | U45: =U44-1 -> 31 | V45: =IF(U45>=0,-PMT($C$5/12,$C$6,$C$4,,0)) -> 415.1671 | W45: =IF(U45>=0,-CUMIPMT($C$5/12,$C$6,$C$4,A45,A45,0)) -> 88.2925 | X45: =V45-W45 -> 326.8746 | Y45: =R45+X45 -> -11445.459 | Z45: =S45+W45 -> -1424.7216 | AA45: =Y45+Z45 -> -12870.18
A46: =IF(A45<$C$6,A45+1,"") -> 30 | B46: =(C46-DATE(1970,1,1))*(24*60*60) -> 1696204800 | C46: =C45+$C$7 -> 45201 | D46: =L45 -> -2003.8565 | E46: =M45 -> 0.33926127 | F46: =IF($J$2=1,IFERROR(VLOOKUP(B46,INDEX_BTCUSD_1D!$A$1:$I$5543,$J$3,0),0),IFERROR(VLOOKUP(B46,INDEX_BTCUSD_1D!$A$1:$I$5543,$J$3,0),0)*IFERROR(VLOOKUP(B46,FX_USDMXN_1D!$A$1:$F$4614,$J$5),0)) -> 27998.64 | G46: =E46*F46 -> 9498.8541 | H46: =D46+G46 -> 7494.9976 | I46: =-V46 -> -415.1671 | J46: 0 | K46: =-J46*F46 -> 0 | L46: =D46+I46+K46 -> -2419.0236 | M46: =E46+J46 -> 0.33926127 | N46: =IF($J$2=1,IFERROR(VLOOKUP(B46,INDEX_BTCUSD_1D!$A$1:$I$5543,$J$4,0),0),IFERROR(VLOOKUP(B46,INDEX_BTCUSD_1D!$A$1:$I$5543,$J$4,0),0)*IFERROR(VLOOKUP(B46,FX_USDMXN_1D!$A$1:$F$4614,$J$6),0)) -> 27510.99 | O46: =M46*N46 -> 9333.4134 | P46: =L46+O46 -> 6914.3897 | Q46: =IF(AND(ISNUMBER(A46)=1,C46<$F$9),(P46+R46)/$C$4,"") -> -0.22655345 | R46: =Y45 -> -11445.459 | S46: =Z45 -> -1424.7216 | T46: =AA45 -> -12870.18 | U46: =U45-1 -> 30 | V46: =IF(U46>=0,-PMT($C$5/12,$C$6,$C$4,,0)) -> 415.1671 | W46: =IF(U46>=0,-CUMIPMT($C$5/12,$C$6,$C$4,A46,A46,0)) -> 85.84094 | X46: =V46-W46 -> 329.32616 | Y46: =R46+X46 -> -11116.133 | Z46: =S46+W46 -> -1338.8806 | AA46: =Y46+Z46 -> -12455.013
A47: =IF(A46<$C$6,A46+1,"") -> 31 | B47: =(C47-DATE(1970,1,1))*(24*60*60) -> 1698796800 | C47: =C46+$C$7 -> 45231 | D47: =L46 -> -2419.0236 | E47: =M46 -> 0.33926127 | F47: =IF($J$2=1,IFERROR(VLOOKUP(B47,INDEX_BTCUSD_1D!$A$1:$I$5543,$J$3,0),0),IFERROR(VLOOKUP(B47,INDEX_BTCUSD_1D!$A$1:$I$5543,$J$3,0),0)*IFERROR(VLOOKUP(B47,FX_USDMXN_1D!$A$1:$F$4614,$J$5),0)) -> 34661.82 | G47: =E47*F47 -> 11759.413 | H47: =D47+G47 -> 9340.3894 | I47: =-V47 -> -415.1671 | J47: 0 | K47: =-J47*F47 -> 0 | L47: =D47+I47+K47 -> -2834.1907 | M47: =E47+J47 -> 0.33926127 | N47: =IF($J$2=1,IFERROR(VLOOKUP(B47,INDEX_BTCUSD_1D!$A$1:$I$5543,$J$4,0),0),IFERROR(VLOOKUP(B47,INDEX_BTCUSD_1D!$A$1:$I$5543,$J$4,0),0)*IFERROR(VLOOKUP(B47,FX_USDMXN_1D!$A$1:$F$4614,$J$6),0)) -> 35442.2 | O47: =M47*N47 -> 12024.166 | P47: =L47+O47 -> 9189.975 | Q47: =IF(AND(ISNUMBER(A47)=1,C47<$F$9),(P47+R47)/$C$4,"") -> -0.096307876 | R47: =Y46 -> -11116.133 | S47: =Z46 -> -1338.8806 | T47: =AA46 -> -12455.013 | U47: =U46-1 -> 29 | V47: =IF(U47>=0,-PMT($C$5/12,$C$6,$C$4,,0)) -> 415.1671 | W47: =IF(U47>=0,-CUMIPMT($C$5/12,$C$6,$C$4,A47,A47,0)) -> 83.370994 | X47: =V47-W47 -> 331.79611 | Y47: =R47+X47 -> -10784.336 | Z47: =S47+W47 -> -1255.5096 | AA47: =Y47+Z47 -> -12039.846
A48: =IF(A47<$C$6,A47+1,"") -> 32 | B48: =(C48-DATE(1970,1,1))*(24*60*60) -> 1701388800 | C48: =C47+$C$7 -> 45261 | D48: =L47 -> -2834.1907 | E48: =M47 -> 0.33926127 | F48: =IF($J$2=1,IFERROR(VLOOKUP(B48,INDEX_BTCUSD_1D!$A$1:$I$5543,$J$3,0),0),IFERROR(VLOOKUP(B48,INDEX_BTCUSD_1D!$A$1:$I$5543,$J$3,0),0)*IFERROR(VLOOKUP(B48,FX_USDMXN_1D!$A$1:$F$4614,$J$5),0)) -> 37728.57 | G48: =E48*F48 -> 12799.843 | H48: =D48+G48 -> 9965.6518 | I48: =-V48 -> -415.1671 | J48: 0 | K48: =-J48*F48 -> 0 | L48: =D48+I48+K48 -> -3249.3579 | M48: =E48+J48 -> 0.33926127 | N48: =IF($J$2=1,IFERROR(VLOOKUP(B48,INDEX_BTCUSD_1D!$A$1:$I$5543,$J$4,0),0),IFERROR(VLOOKUP(B48,INDEX_BTCUSD_1D!$A$1:$I$5543,$J$4,0),0)*IFERROR(VLOOKUP(B48,FX_USDMXN_1D!$A$1:$F$4614,$J$6),0)) -> 38694.14 | O48: =M48*N48 -> 13127.423 | P48: =L48+O48 -> 9878.0652 | Q48: =IF(AND(ISNUMBER(A48)=1,C48<$F$9),(P48+R48)/$C$4,"") -> -0.045313561 | R48: =Y47 -> -10784.336 | S48: =Z47 -> -1255.5096 | T48: =AA47 -> -12039.846 | U48: =U47-1 -> 28 | V48: =IF(U48>=0,-PMT($C$5/12,$C$6,$C$4,,0)) -> 415.1671 | W48: =IF(U48>=0,-CUMIPMT($C$5/12,$C$6,$C$4,A48,A48,0)) -> 80.882523 | X48: =V48-W48 -> 334.28458 | Y48: =R48+X48 -> -10450.052 | Z48: =S48+W48 -> -1174.6271 | AA48: =Y48+Z48 -> -11624.679
A49: =IF(A48<$C$6,A48+1,"") -> 33 | B49: =(C49-DATE(1970,1,1))*(24*60*60) -> 1703980800 | C49: =C48+$C$7 -> 45291 | D49: =L48 -> -3249.3579 | E49: =M48 -> 0.33926127 | F49: =IF($J$2=1,IFERROR(VLOOKUP(B49,INDEX_BTCUSD_1D!$A$1:$I$5543,$J$3,0),0),IFERROR(VLOOKUP(B49,INDEX_BTCUSD_1D!$A$1:$I$5543,$J$3,0),0)*IFERROR(VLOOKUP(B49,FX_USDMXN_1D!$A$1:$F$4614,$J$5),0)) -> 42158.86 | G49: =E49*F49 -> 14302.868 | H49: =D49+G49 -> 11053.511 | I49: =-V49 -> -415.1671 | J49: 0 | K49: =-J49*F49 -> 0 | L49: =D49+I49+K49 -> -3664.525 | M49: =E49+J49 -> 0.33926127 | N49: =IF($J$2=1,IFERROR(VLOOKUP(B49,INDEX_BTCUSD_1D!$A$1:$I$5543,$J$4,0),0),IFERROR(VLOOKUP(B49,INDEX_BTCUSD_1D!$A$1:$I$5543,$J$4,0),0)*IFERROR(VLOOKUP(B49,FX_USDMXN_1D!$A$1:$F$4614,$J$6),0)) -> 42278.29 | O49: =M49*N49 -> 14343.386 | P49: =L49+O49 -> 10678.861 | Q49: =IF(AND(ISNUMBER(A49)=1,C49<$F$9),(P49+R49)/$C$4,"") -> 0.011440477 | R49: =Y48 -> -10450.052 | S49: =Z48 -> -1174.6271 | T49: =AA48 -> -11624.679 | U49: =U48-1 -> 27 | V49: =IF(U49>=0,-PMT($C$5/12,$C$6,$C$4,,0)) -> 415.1671 | W49: =IF(U49>=0,-CUMIPMT($C$5/12,$C$6,$C$4,A49,A49,0)) -> 78.375389 | X49: =V49-W49 -> 336.79172 | Y49: =R49+X49 -> -10113.26 | Z49: =S49+W49 -> -1096.2517 | AA49: =Y49+Z49 -> -11209.512
A50: =IF(A49<$C$6,A49+1,"") -> 34 | B50: =(C50-DATE(1970,1,1))*(24*60*60) -> 1706572800 | C50: =C49+$C$7 -> 45321 | D50: =L49 -> -3664.525 | E50: =M49 -> 0.33926127 | F50: =IF($J$2=1,IFERROR(VLOOKUP(B50,INDEX_BTCUSD_1D!$A$1:$I$5543,$J$3,0),0),IFERROR(VLOOKUP(B50,INDEX_BTCUSD_1D!$A$1:$I$5543,$J$3,0),0)*IFERROR(VLOOKUP(B50,FX_USDMXN_1D!$A$1:$F$4614,$J$5),0)) -> 43296.75 | G50: =E50*F50 -> 14688.91 | H50: =D50+G50 -> 11024.385 | I50: =-V50 -> -415.1671 | J50: 0 | K50: =-J50*F50 -> 0 | L50: =D50+I50+K50 -> -4079.6921 | M50: =E50+J50 -> 0.33926127 | N50: =IF($J$2=1,IFERROR(VLOOKUP(B50,INDEX_BTCUSD_1D!$A$1:$I$5543,$J$4,0),0),IFERROR(VLOOKUP(B50,INDEX_BTCUSD_1D!$A$1:$I$5543,$J$4,0),0)*IFERROR(VLOOKUP(B50,FX_USDMXN_1D!$A$1:$F$4614,$J$6),0)) -> 42950.2 | O50: =M50*N50 -> 14571.339 | P50: =L50+O50 -> 10491.647 | Q50: =IF(AND(ISNUMBER(A50)=1,C50<$F$9),(P50+R50)/$C$4,"") -> 0.01891936 | R50: =Y49 -> -10113.26 | S50: =Z49 -> -1096.2517 | T50: =AA49 -> -11209.512 | U50: =U49-1 -> 26 | V50: =IF(U50>=0,-PMT($C$5/12,$C$6,$C$4,,0)) -> 415.1671 | W50: =IF(U50>=0,-CUMIPMT($C$5/12,$C$6,$C$4,A50,A50,0)) -> 75.849451 | X50: =V50-W50 -> 339.31765 | Y50: =R50+X50 -> -9773.9425 | Z50: =S50+W50 -> -1020.4023 | AA50: =Y50+Z50 -> -10794.345
A51: =IF(A50<$C$6,A50+1,"") -> 35 | B51: =(C51-DATE(1970,1,1))*(24*60*60) -> 1709164800 | C51: =C50+$C$7 -> 45351 | D51: =L50 -> -4079.6921 | E51: =M50 -> 0.33926127 | F51: =IF($J$2=1,IFERROR(VLOOKUP(B51,INDEX_BTCUSD_1D!$A$1:$I$5543,$J$3,0),0),IFERROR(VLOOKUP(B51,INDEX_BTCUSD_1D!$A$1:$I$5543,$J$3,0),0)*IFERROR(VLOOKUP(B51,FX_USDMXN_1D!$A$1:$F$4614,$J$5),0)) -> 62473.97 | G51: =E51*F51 -> 21194.998 | H51: =D51+G51 -> 17115.306 | I51: =-V51 -> -415.1671 | J51: 0 | K51: =-J51*F51 -> 0 | L51: =D51+I51+K51 -> -4494.8592 | M51: =E51+J51 -> 0.33926127 | N51: =IF($J$2=1,IFERROR(VLOOKUP(B51,INDEX_BTCUSD_1D!$A$1:$I$5543,$J$4,0),0),IFERROR(VLOOKUP(B51,INDEX_BTCUSD_1D!$A$1:$I$5543,$J$4,0),0)*IFERROR(VLOOKUP(B51,FX_USDMXN_1D!$A$1:$F$4614,$J$6),0)) -> 61165.98 | O51: =M51*N51 -> 20751.248 | P51: =L51+O51 -> 16256.389 | Q51: =IF(AND(ISNUMBER(A51)=1,C51<$F$9),(P51+R51)/$C$4,"") -> 0.32412232 | R51: =Y50 -> -9773.9425 | S51: =Z50 -> -1020.4023 | T51: =AA50 -> -10794.345 | U51: =U50-1 -> 25 | V51: =IF(U51>=0,-PMT($C$5/12,$C$6,$C$4,,0)) -> 415.1671 | W51: =IF(U51>=0,-CUMIPMT($C$5/12,$C$6,$C$4,A51,A51,0)) -> 73.304568 | X51: =V51-W51 -> 341.86254 | Y51: =R51+X51 -> -9432.0799 | Z51: =S51+W51 -> -947.09769 | AA51: =Y51+Z51 -> -10379.178
A52: =IF(A51<$C$6,A51+1,"") -> 36 | B52: =(C52-DATE(1970,1,1))*(24*60*60) -> 1711756800 | C52: =C51+$C$7 -> 45381 | D52: =L51 -> -4494.8592 | E52: =M51 -> 0.33926127 | F52: =IF($J$2=1,IFERROR(VLOOKUP(B52,INDEX_BTCUSD_1D!$A$1:$I$5543,$J$3,0),0),IFERROR(VLOOKUP(B52,INDEX_BTCUSD_1D!$A$1:$I$5543,$J$3,0),0)*IFERROR(VLOOKUP(B52,FX_USDMXN_1D!$A$1:$F$4614,$J$5),0)) -> 69904.44 | G52: =E52*F52 -> 23715.869 | H52: =D52+G52 -> 19221.01 | I52: =-V52 -> -415.1671 | J52: 0 | K52: =-J52*F52 -> 0 | L52: =D52+I52+K52 -> -4910.0263 | M52: =E52+J52 -> 0.33926127 | N52: =IF($J$2=1,IFERROR(VLOOKUP(B52,INDEX_BTCUSD_1D!$A$1:$I$5543,$J$4,0),0),IFERROR(VLOOKUP(B52,INDEX_BTCUSD_1D!$A$1:$I$5543,$J$4,0),0)*IFERROR(VLOOKUP(B52,FX_USDMXN_1D!$A$1:$F$4614,$J$6),0)) -> 69640.22 | O52: =M52*N52 -> 23626.229 | P52: =L52+O52 -> 18716.203 | Q52: =IF(AND(ISNUMBER(A52)=1,C52<$F$9),(P52+R52)/$C$4,"") -> 0.46420616 | R52: =Y51 -> -9432.0799 | S52: =Z51 -> -947.09769 | T52: =AA51 -> -10379.178 | U52: =U51-1 -> 24 | V52: =IF(U52>=0,-PMT($C$5/12,$C$6,$C$4,,0)) -> 415.1671 | W52: =IF(U52>=0,-CUMIPMT($C$5/12,$C$6,$C$4,A52,A52,0)) -> 70.740599 | X52: =V52-W52 -> 344.42651 | Y52: =R52+X52 -> -9087.6534 | Z52: =S52+W52 -> -876.35709 | AA52: =Y52+Z52 -> -9964.0105
...

Sheet Promedio de costo
A1: Ahorrar: | B1: 100 | C1: =$N$2 -> MXN | E1: Promedio de Costo 0.1.6
A2: Cada: | B2: 7 | C2: días | E2: autor: | F2: bc1q9athlkl0nypmhatx8mgepgsdn8ut8wfvpejh7t | M2: 0 | N2: =IF(M2=1,"USD","MXN") -> MXN | O2: (0 / default = MXN, 1 = USD) | S2: log
A3: Por: | B3: 4 | C3: años | E3: last update: | F3: 928932 | G3: 0590 | M3: 0 | N3: diff first buy | O3: =B1*2 -> 200 | P3: =N2 -> MXN | Q3: (0 = off; 1 = on) | S3: 0.1.4 | T3: added USD support
M4: 0 | N4: smart dca | O4: -0.07 | P4: from previous close price | T4: left only 120 periods displayed
S5: 0.1.5 | T5: added first buy different from all buys
T6: testing smart dca:
T7: buy only after -% from previous close
B8: UNIX | C8: FECHA | D8: BTCUSD | E8: USDMXN | G8: ACUMULADO | H8: VALOR | I8: VALOR | J8: AHORRASTE | K8: RETORNO DE AHORRO | T8: price, if not accumulate fiat
A9: Inicio: | B9: =(C9-DATE(1970,1,1))*(24*60*60) -> 1633046400 | C9: 44470 | D9: =VLOOKUP(B9,$B$15:$K$223,3,0) -> 48166.92 | E9: =VLOOKUP(B9,$B$15:$K$223,4,0) -> 20.435 | G9: BTC | H9: USD | I9: MXN | J9: =$N$2 -> MXN | S9: 0.1.6 | T9: up to 209 periods displayed
A10: Fin: | B10: =(B9+24*60*60*7*52*B3) -> 1758844800 | C10: =B10/(24*60*60)+DATE(1970,1,1) -> 45926 | D10: =IFERROR(VLOOKUP(B10,$B$15:$K$223,3,0),"") -> 109757.4 | E10: =IF(ISNUMBER(D10),VLOOKUP(B10,$B$15:$K$223,4),"") -> 18.3589 | G10: =IF(VLOOKUP(2,$A$14:$K$223,2,0)=($C$10-DATE(1970,1,1))*(24*60*60),VLOOKUP(2,$A$14:$K$223,7),"") -> 0.02885913 | H10: =IF(VLOOKUP(2,$A$14:$K$223,2,0)=($C$10-DATE(1970,1,1))*(24*60*60),VLOOKUP(2,$A$14:$K$223,8),"") -> 3167.5031 | I10: =IF(VLOOKUP(2,$A$14:$K$223,2,0)=($C$10-DATE(1970,1,1))*(24*60*60),VLOOKUP(2,$A$14:$K$223,9),"") -> 58151.872 | J10: =IF(VLOOKUP(2,$A$14:$K$223,2,0)=($C$10-DATE(1970,1,1))*(24*60*60),VLOOKUP(2,$A$14:$K$223,10),"") -> 20900 | K10: =IF(VLOOKUP(2,$A$14:$K$223,2,0)=($C$10-DATE(1970,1,1))*(24*60*60),VLOOKUP(2,$A$14:$K$223,11),"") -> 1.7823862 | T10: fixed bugs
A12: Actual: | B12: =(C12-DATE(1970,1,1))*(24*60*60) -> 1765670400 | C12: 46005 | D12: =VLOOKUP(B12,INDEX_BTCUSD_1D!$A$1:$I$5825,6) -> 90272.63 | E12: =VLOOKUP(B12,FX_USDMXN_1D!A1:F4816,6) -> 18.0109 | G12: =VLOOKUP(2,$A$14:$K$223,7,0) -> 0.02885913 | H12: =$G$12*D12 -> 2605.1896 | I12: =$G$12*D12*E12 -> 46921.809 | J12: =VLOOKUP(2,$A$14:$K$223,10,0) -> 20900 | K12: ==IF($M$2=1,H12/J12-1,I12/J12-1) -> 1.2450626 | S12: letusnetwork.com
A14: filter | B14: unix time | C14: matrix time | D14: close BTCUSD | E14: close USDMXN | F14: buys BTC | G14: accumulated BTC | H14: current value USD | I14: current value MXN | J14: =_xlfn.CONCAT("spent ",$N$2) -> spent MXN | K14: return % | M14: change prev close price (%) | O14: smart dca buys | P14: pending
A15: =IF(IFERROR(C15,0)=0,0,IF(B15>$B$10,0,IF(A16=0,2,1))) -> 1 | B15: =B9 -> 1633046400 | C15: =VLOOKUP(B15,INDEX_BTCUSD_1D!$A$1:$I$5825,2,0) -> 44470 | D15: =VLOOKUP(B15,INDEX_BTCUSD_1D!$A$1:$I$5825,9,0) -> 48166.92 | E15: =VLOOKUP(B15,FX_USDMXN_1D!$A$1:$F$4816,6) -> 20.435 | F15: =IF(M3=1,IF($M$2=1,$O$3/D15,$O$3/E15/D15),IF($M$2=1,$B$1/D15,$B$1/E15/D15)) -> 0.00010159597 | G15: =F15 -> 0.00010159597 | H15: =G15*D15 -> 4.893565 | I15: =G15*D15*E15 -> 100 | J15: =IF(M3=1,O3,$B$1*COUNT($B$15:B15)) -> 100 | K15: =IF($M$2=1,H15/J15-1,I15/J15-1) -> 0 | M15: =D15/VLOOKUP(B15-$B$2*24*60*60,INDEX_BTCUSD_1D!$A$1:$I$5825,9,0)-1 -> 0.12422277 | N15: =IF(M15<=$O$4,1,0) -> 0 | O15: =IF(N15=1,IF(M3=1,IF($M$2=1,$O$3/D15,$O$3/E15/D15),IF($M$2=1,$B$1/D15,$B$1/E15/D15)),0) -> 0 | P15: =IF(N15=0,B1,O3) -> 100
A16: =IF(IFERROR(C16,0)=0,0,IF(B16>(($C$10-DATE(1970,1,1))*(24*60*60)),0,IF(A17=0,2,1))) -> 1 | B16: =B15+$B$2*24*60*60 -> 1633651200 | C16: =VLOOKUP(B16,INDEX_BTCUSD_1D!$A$1:$I$5825,2,0) -> 44477 | D16: =VLOOKUP(B16,INDEX_BTCUSD_1D!$A$1:$I$5825,9,0) -> 53957.732 | E16: =VLOOKUP(B16,FX_USDMXN_1D!$A$1:$F$4816,6) -> 20.6816 | F16: =IF($M$2=1,$B$1/D16,$B$1/E16/D16) -> 8.9611176e-05 | G16: =F16+G15 -> 0.00019120715 | H16: =G16*D16 -> 10.317104 | I16: =G16*D16*E16 -> 213.37422 | J16: =J15+$B$1 -> 200 | K16: =IF($M$2=1,H16/J16-1,I16/J16-1) -> 0.066871092 | M16: =D16/D15-1 -> 0.12022385 | N16: =IF(M16<=$O$4,1,0) -> 0 | O16: =IF(N16=1,IF($M$2=1,($B$1+P15)/D16,($B$1+P15)/E16/D16),0) -> 0 | P16: =IF(N16=0,$B$1+P15,0) -> 200
A17: =IF(IFERROR(C17,0)=0,0,IF(B17>(($C$10-DATE(1970,1,1))*(24*60*60)),0,IF(A18=0,2,1))) -> 1 | B17: =B16+$B$2*24*60*60 -> 1634256000 | C17: =VLOOKUP(B17,INDEX_BTCUSD_1D!$A$1:$I$5825,2,0) -> 44484 | D17: =VLOOKUP(B17,INDEX_BTCUSD_1D!$A$1:$I$5825,9,0) -> 61668.588 | E17: =VLOOKUP(B17,FX_USDMXN_1D!$A$1:$F$4816,6) -> 20.322 | F17: =IF($M$2=1,$B$1/D17,$B$1/E17/D17) -> 7.9793874e-05 | G17: =F17+G16 -> 0.00027100102 | H17: =G17*D17 -> 16.71225 | I17: =G17*D17*E17 -> 339.62635 | J17: =J16+$B$1 -> 300 | K17: =IF($M$2=1,H17/J17-1,I17/J17-1) -> 0.13208782 | M17: =D17/D16-1 -> 0.14290547 | N17: =IF(M17<=$O$4,1,0) -> 0 | O17: =IF(N17=1,IF($M$2=1,($B$1+P16)/D17,($B$1+P16)/E17/D17),0) -> 0 | P17: =IF(N17=0,$B$1+P16,0) -> 300
A18: =IF(IFERROR(C18,0)=0,0,IF(B18>(($C$10-DATE(1970,1,1))*(24*60*60)),0,IF(A19=0,2,1))) -> 1 | B18: =B17+$B$2*24*60*60 -> 1634860800 | C18: =VLOOKUP(B18,INDEX_BTCUSD_1D!$A$1:$I$5825,2,0) -> 44491 | D18: =VLOOKUP(B18,INDEX_BTCUSD_1D!$A$1:$I$5825,9,0) -> 60693.442 | E18: =VLOOKUP(B18,FX_USDMXN_1D!$A$1:$F$4816,6) -> 20.1542 | F18: =IF($M$2=1,$B$1/D18,$B$1/E18/D18) -> 8.1750923e-05 | G18: =F18+G17 -> 0.00035275194 | H18: =G18*D18 -> 21.40973 | I18: =G18*D18*E18 -> 431.49598 | J18: =J17+$B$1 -> 400 | K18: =IF($M$2=1,H18/J18-1,I18/J18-1) -> 0.078739939 | M18: =D18/D17-1 -> -0.01581267 | N18: =IF(M18<=$O$4,1,0) -> 0 | O18: =IF(N18=1,IF($M$2=1,($B$1+P17)/D18,($B$1+P17)/E18/D18),0) -> 0 | P18: =IF(N18=0,$B$1+P17,0) -> 400
A19: =IF(IFERROR(C19,0)=0,0,IF(B19>(($C$10-DATE(1970,1,1))*(24*60*60)),0,IF(A20=0,2,1))) -> 1 | B19: =B18+$B$2*24*60*60 -> 1635465600 | C19: =VLOOKUP(B19,INDEX_BTCUSD_1D!$A$1:$I$5825,2,0) -> 44498 | D19: =VLOOKUP(B19,INDEX_BTCUSD_1D!$A$1:$I$5825,9,0) -> 62279.402 | E19: =VLOOKUP(B19,FX_USDMXN_1D!$A$1:$F$4816,6) -> 20.5349 | F19: =IF($M$2=1,$B$1/D19,$B$1/E19/D19) -> 7.8192117e-05 | G19: =F19+G18 -> 0.00043094406 | H19: =G19*D19 -> 26.838939 | I19: =G19*D19*E19 -> 551.13492 | J19: =J18+$B$1 -> 500 | K19: =IF($M$2=1,H19/J19-1,I19/J19-1) -> 0.10226984 | M19: =D19/D18-1 -> 0.026130665 | N19: =IF(M19<=$O$4,1,0) -> 0 | O19: =IF(N19=1,IF($M$2=1,($B$1+P18)/D19,($B$1+P18)/E19/D19),0) -> 0 | P19: =IF(N19=0,$B$1+P18,0) -> 500
A20: =IF(IFERROR(C20,0)=0,0,IF(B20>(($C$10-DATE(1970,1,1))*(24*60*60)),0,IF(A21=0,2,1))) -> 1 | B20: =B19+$B$2*24*60*60 -> 1636070400 | C20: =VLOOKUP(B20,INDEX_BTCUSD_1D!$A$1:$I$5825,2,0) -> 44505 | D20: =VLOOKUP(B20,INDEX_BTCUSD_1D!$A$1:$I$5825,9,0) -> 61016.158 | E20: =VLOOKUP(B20,FX_USDMXN_1D!$A$1:$F$4816,6) -> 20.3189 | F20: =IF($M$2=1,$B$1/D20,$B$1/E20/D20) -> 8.0659394e-05 | G20: =F20+G19 -> 0.00051160345 | H20: =G20*D20 -> 31.216077 | I20: =G20*D20*E20 -> 634.27634 | J20: =J19+$B$1 -> 600 | K20: =IF($M$2=1,H20/J20-1,I20/J20-1) -> 0.057127241 | M20: =D20/D19-1 -> -0.020283512 | N20: =IF(M20<=$O$4,1,0) -> 0 | O20: =IF(N20=1,IF($M$2=1,($B$1+P19)/D20,($B$1+P19)/E20/D20),0) -> 0 | P20: =IF(N20=0,$B$1+P19,0) -> 600
A21: =IF(IFERROR(C21,0)=0,0,IF(B21>(($C$10-DATE(1970,1,1))*(24*60*60)),0,IF(A22=0,2,1))) -> 1 | B21: =B20+$B$2*24*60*60 -> 1636675200 | C21: =VLOOKUP(B21,INDEX_BTCUSD_1D!$A$1:$I$5825,2,0) -> 44512 | D21: =VLOOKUP(B21,INDEX_BTCUSD_1D!$A$1:$I$5825,9,0) -> 64153.327 | E21: =VLOOKUP(B21,FX_USDMXN_1D!$A$1:$F$4816,6) -> 20.5161 | F21: =IF($M$2=1,$B$1/D21,$B$1/E21/D21) -> 7.5977676e-05 | G21: =F21+G20 -> 0.00058758113 | H21: =G21*D21 -> 37.695285 | I21: =G21*D21*E21 -> 773.36023 | J21: =J20+$B$1 -> 700 | K21: =IF($M$2=1,H21/J21-1,I21/J21-1) -> 0.10480033 | M21: =D21/D20-1 -> 0.051415398 | N21: =IF(M21<=$O$4,1,0) -> 0 | O21: =IF(N21=1,IF($M$2=1,($B$1+P20)/D21,($B$1+P20)/E21/D21),0) -> 0 | P21: =IF(N21=0,$B$1+P20,0) -> 700
A22: =IF(IFERROR(C22,0)=0,0,IF(B22>(($C$10-DATE(1970,1,1))*(24*60*60)),0,IF(A23=0,2,1))) -> 1 | B22: =B21+$B$2*24*60*60 -> 1637280000 | C22: =VLOOKUP(B22,INDEX_BTCUSD_1D!$A$1:$I$5825,2,0) -> 44519 | D22: =VLOOKUP(B22,INDEX_BTCUSD_1D!$A$1:$I$5825,9,0) -> 58067.598 | E22: =VLOOKUP(B22,FX_USDMXN_1D!$A$1:$F$4816,6) -> 20.8238 | F22: =IF($M$2=1,$B$1/D22,$B$1/E22/D22) -> 8.2700124e-05 | G22: =F22+G21 -> 0.00067028125 | H22: =G22*D22 -> 38.921622 | I22: =G22*D22*E22 -> 810.49607 | J22: =J21+$B$1 -> 800 | K22: =IF($M$2=1,H22/J22-1,I22/J22-1) -> 0.01312009 | M22: =D22/D21-1 -> -0.094862266 | N22: =IF(M22<=$O$4,1,0) -> 1 | O22: =IF(N22=1,IF($M$2=1,($B$1+P21)/D22,($B$1+P21)/E22/D22),0) -> 0.00066160099 | P22: =IF(N22=0,$B$1+P21,0) -> 0
A23: =IF(IFERROR(C23,0)=0,0,IF(B23>(($C$10-DATE(1970,1,1))*(24*60*60)),0,IF(A24=0,2,1))) -> 1 | B23: =B22+$B$2*24*60*60 -> 1637884800 | C23: =VLOOKUP(B23,INDEX_BTCUSD_1D!$A$1:$I$5825,2,0) -> 44526 | D23: =VLOOKUP(B23,INDEX_BTCUSD_1D!$A$1:$I$5825,9,0) -> 53871.287 | E23: =VLOOKUP(B23,FX_USDMXN_1D!$A$1:$F$4816,6) -> 21.8998 | F23: =IF($M$2=1,$B$1/D23,$B$1/E23/D23) -> 8.4762254e-05 | G23: =F23+G22 -> 0.00075504351 | H23: =G23*D23 -> 40.675166 | I23: =G23*D23*E23 -> 890.778 | J23: =J22+$B$1 -> 900 | K23: =IF($M$2=1,H23/J23-1,I23/J23-1) -> -0.01024667 | M23: =D23/D22-1 -> -0.072265948 | N23: =IF(M23<=$O$4,1,0) -> 1 | O23: =IF(N23=1,IF($M$2=1,($B$1+P22)/D23,($B$1+P22)/E23/D23),0) -> 8.4762254e-05 | P23: =IF(N23=0,$B$1+P22,0) -> 0
A24: =IF(IFERROR(C24,0)=0,0,IF(B24>(($C$10-DATE(1970,1,1))*(24*60*60)),0,IF(A25=0,2,1))) -> 1 | B24: =B23+$B$2*24*60*60 -> 1638489600 | C24: =VLOOKUP(B24,INDEX_BTCUSD_1D!$A$1:$I$5825,2,0) -> 44533 | D24: =VLOOKUP(B24,INDEX_BTCUSD_1D!$A$1:$I$5825,9,0) -> 53683.26 | E24: =VLOOKUP(B24,FX_USDMXN_1D!$A$1:$F$4816,6) -> 21.2556 | F24: =IF($M$2=1,$B$1/D24,$B$1/E24/D24) -> 8.763705e-05 | G24: =F24+G23 -> 0.00084268056 | H24: =G24*D24 -> 45.237839 | I24: =G24*D24*E24 -> 961.55742 | J24: =J23+$B$1 -> 1000 | K24: =IF($M$2=1,H24/J24-1,I24/J24-1) -> -0.03844258 | M24: =D24/D23-1 -> -0.0034903101 | N24: =IF(M24<=$O$4,1,0) -> 0 | O24: =IF(N24=1,IF($M$2=1,($B$1+P23)/D24,($B$1+P23)/E24/D24),0) -> 0 | P24: =IF(N24=0,$B$1+P23,0) -> 100
A25: =IF(IFERROR(C25,0)=0,0,IF(B25>(($C$10-DATE(1970,1,1))*(24*60*60)),0,IF(A26=0,2,1))) -> 1 | B25: =B24+$B$2*24*60*60 -> 1639094400 | C25: =VLOOKUP(B25,INDEX_BTCUSD_1D!$A$1:$I$5825,2,0) -> 44540 | D25: =VLOOKUP(B25,INDEX_BTCUSD_1D!$A$1:$I$5825,9,0) -> 47229.01 | E25: =VLOOKUP(B25,FX_USDMXN_1D!$A$1:$F$4816,6) -> 20.8714 | F25: =IF($M$2=1,$B$1/D25,$B$1/E25/D25) -> 0.00010144709 | G25: =F25+G24 -> 0.00094412764 | H25: =G25*D25 -> 44.590214 | I25: =G25*D25*E25 -> 930.66019 | J25: =J24+$B$1 -> 1100 | K25: =IF($M$2=1,H25/J25-1,I25/J25-1) -> -0.15394528 | M25: =D25/D24-1 -> -0.12022835 | N25: =IF(M25<=$O$4,1,0) -> 1 | O25: =IF(N25=1,IF($M$2=1,($B$1+P24)/D25,($B$1+P24)/E25/D25),0) -> 0.00020289417 | P25: =IF(N25=0,$B$1+P24,0) -> 0
A26: =IF(IFERROR(C26,0)=0,0,IF(B26>(($C$10-DATE(1970,1,1))*(24*60*60)),0,IF(A27=0,2,1))) -> 1 | B26: =B25+$B$2*24*60*60 -> 1639699200 | C26: =VLOOKUP(B26,INDEX_BTCUSD_1D!$A$1:$I$5825,2,0) -> 44547 | D26: =VLOOKUP(B26,INDEX_BTCUSD_1D!$A$1:$I$5825,9,0) -> 46216.71 | E26: =VLOOKUP(B26,FX_USDMXN_1D!$A$1:$F$4816,6) -> 20.811 | F26: =IF($M$2=1,$B$1/D26,$B$1/E26/D26) -> 0.00010397 | G26: =F26+G25 -> 0.0010480976 | H26: =G26*D26 -> 48.439625 | I26: =G26*D26*E26 -> 1008.077 | J26: =J25+$B$1 -> 1200 | K26: =IF($M$2=1,H26/J26-1,I26/J26-1) -> -0.15993581 | M26: =D26/D25-1 -> -0.02143386 | N26: =IF(M26<=$O$4,1,0) -> 0 | O26: =IF(N26=1,IF($M$2=1,($B$1+P25)/D26,($B$1+P25)/E26/D26),0) -> 0 | P26: =IF(N26=0,$B$1+P25,0) -> 100
A27: =IF(IFERROR(C27,0)=0,0,IF(B27>(($C$10-DATE(1970,1,1))*(24*60*60)),0,IF(A28=0,2,1))) -> 1 | B27: =B26+$B$2*24*60*60 -> 1640304000 | C27: =VLOOKUP(B27,INDEX_BTCUSD_1D!$A$1:$I$5825,2,0) -> 44554 | D27: =VLOOKUP(B27,INDEX_BTCUSD_1D!$A$1:$I$5825,9,0) -> 50835.68 | E27: =VLOOKUP(B27,FX_USDMXN_1D!$A$1:$F$4816,6) -> 20.6126 | F27: =IF($M$2=1,$B$1/D27,$B$1/E27/D27) -> 9.5433002e-05 | G27: =F27+G26 -> 0.0011435306 | H27: =G27*D27 -> 58.132158 | I27: =G27*D27*E27 -> 1198.2549 | J27: =J26+$B$1 -> 1300 | K27: =IF($M$2=1,H27/J27-1,I27/J27-1) -> -0.078265451 | M27: =D27/D26-1 -> 0.099941558 | N27: =IF(M27<=$O$4,1,0) -> 0 | O27: =IF(N27=1,IF($M$2=1,($B$1+P26)/D27,($B$1+P26)/E27/D27),0) -> 0 | P27: =IF(N27=0,$B$1+P26,0) -> 200
... A223: =IF(IFERROR(C223,0)=0,0,IF(B223>(($C$10-DATE(1970,1,1))*(24*60*60)),0,IF(A224=0,2,1))) -> 2 | B223: =B222+$B$2*24*60*60 -> 1758844800 | C223: =VLOOKUP(B223,INDEX_BTCUSD_1D!$A$1:$I$5825,2,0) -> 45926 | D223: =VLOOKUP(B223,INDEX_BTCUSD_1D!$A$1:$I$5825,9,0) -> 109757.4 | E223: =VLOOKUP(B223,FX_USDMXN_1D!$A$1:$F$4816,6) -> 18.3589 | F223: =IF($M$2=1,$B$1/D223,$B$1/E223/D223) -> 4.9627173e-05 | G223: =F223+G222 -> 0.02885913 | H223: =G223*D223 -> 3167.5031 | I223: =G223*D223*E223 -> 58151.872 | J223: =J222+$B$1 -> 20900 | K223: =IF($M$2=1,H223/J223-1,I223/J223-1) -> 1.7823862 | M223: =D223/D222-1 -> -0.051566585 | N223: =IF(M223<=$O$4,1,0) -> 0 | O223: =IF(N223=1,IF($M$2=1,($B$1+P222)/D223,($B$1+P222)/E223/D223),0) -> 0 | P223: =IF(N223=0,$B$1+P222,0) -> 400

Sheet Financiamiento de auto
B2: VALOR INICIAL DEL AUTO: | C2: 290000 | D2: =$M$2 -> MXN | E2: Financiamiento de auto 0.1.4 | L2: 0 | M2: =IF(L2=1,"USD","MXN") -> MXN | N2: (0 / default = MXN, 1 = USD) | Q2: log
B3: ENGANCHE: | C3: 0.1724138 | E3: autor: | F3: bc1ql4d4v67mts38a5cs0yhxnsu59w40492q9a4y4c | Q3: 0.1.3 | R3: added USD support
B4: TASA DE INTERÉS ANUAL: | C4: 0 | E4: last update: | F4: 928054 | G4: e9bc | Q4: 0.1.4 | R4: updated BTCUSD and
B5: PLAZO: | C5: 48 | D5: MESES | R5: USDMXN data
B6: PAGOS CADA: | C6: 30 | D6: DÍAS | G6: BALANCES | R6: fixed formula cells T27-T74
G7: =$M$2 -> MXN | H7: BTC | I7: TOTAL | J7: RETORNO
B8: INICIO: | C8: 45444 | D8: =(C8-DATE(1970,1,1))*(24*60*60) -> 1717200000
B9: FIN: | C9: =D9/(24*60*60)+DATE(1970,1,1) -> 46904.968 | D9: =D8+48*2629743 -> 1843427664 | F9: ACTUAL SIN USAR BTC: | G9: =SUMIF(N26:N74,0,S26:S73) -> 140000 | H9: 0 | I9: =G9 -> 140000 | J9: =I9/C2-1 -> -0.51724138
B10: HOY: | C10: =D10/(24*60*60)+DATE(1970,1,1) -> 46005 | D10: =INDEX_BTCUSD_1D!P1 -> 1765670400 | F10: ACTUAL: | G10: =LOOKUP(2, 1/(ISNUMBER(H26:H74)),H26:H74) -> 71999.999 | H10: =MAX(I26:I74) -> 0.054210005 | I10: =G10+(H10*VLOOKUP(D10,INDEX_BTCUSD_1D!A1:I5825,6,0)*VLOOKUP(D10,FX_USDMXN_1D!A1:F4816,6)) -> 160139.58 | J10: =I10/C2-1 -> -0.44779457
B12: PRÉSTAMO INICIAL: | C12: =C2-C13 -> 240000 | D12: =$M$2 -> MXN
B13: ENGANCHE: | C13: =C2*C3 -> 50000.002 | D13: =$M$2 -> MXN
B14: MONTO DE CADA PAGO: | C14: =-PMT(C4/12,C5,C12,,0) -> 5000 | D14: =$M$2 -> MXN
B16: COMPRA DE BTC CON: | C16: 1 | D16: DEL ENGANCHE | F16: FINAL SIN USAR BTC: | G16: =C14*C5+C13 -> 290000 | H16: 0 | I16: =G16 -> 290000 | J16: =I16/C2-1 -> 0
B17: COMPRA DE BTC CON: | C17: 0.2 | D17: DE CADA PAGO | F17: FINAL: | G17: =H74 | H17: =I74 | I17: =IFERROR(G17+(H17*Q74),"") | J17: =IFERROR(I17/C2-1,"")
B18: USAR SMART DCA: | C18: 0 | D18: (1 = on, 0 = off) | M18: letusnetwork.com
A21: vendedor
A23: fecha | B23: balance inicial | E23: tipo de cambio | H23: balance final | O23: btcusd | P23: usdmxn | Q23: btcmxn | S23: pymt | T23: dca | U23: total | V23: buy after | X23: smart dca | Y23: total | Z23: pasive | AC23: next pymt | AD23: on interest | AE23: on principal
B24: activo | D24: pasivo | H24: activo | J24: pasivo | L24: unix time | M24: matrix time | N24: future date? | O24: close | P24: close | Q24: close | R24: change % | S24: =LOWER($M$2) -> mxn | T24: btc | U24: =LOWER($M$2) -> mxn | V24: -0.07 | W24: pending | X24: btc | Y24: =LOWER($M$2) -> mxn | Z24: =LOWER($M$2) -> mxn | AA24: payments | AB24: left | AC24: =LOWER($M$2) -> mxn | AD24: =LOWER($M$2) -> mxn | AE24: =LOWER($M$2) -> mxn
B25: =LOWER($M$2) -> mxn | C25: btc | D25: =LOWER($M$2) -> mxn | E25: usdmxn | F25: btcusd | G25: btcmxn | H25: =LOWER($M$2) -> mxn | I25: btc | J25: =LOWER($M$2) -> mxn | L25: =L26-2629743 -> 1714570257 | M25: =L25/(24*60*60)+DATE(1970,1,1) -> 45413.563 | O25: =IF(N26=0,VLOOKUP(L25,INDEX_BTCUSD_1D!$A$1:$I$5825,9),"") -> 58308.7 | Z25: =-C2 -> -290000 | AC25: =C13 -> 50000.002 | AE25: =AC25+AD25 -> 50000.002 | AI25: year | AJ25: =$C$5/12-($C$5/12)+1 -> 1 | AK25: 2 | AL25: 3 | AM25: 4
A26: =M26 -> 45444 | B26: 0 | C26: 0 | D26: 0 | E26: =P26 -> 16.988 | F26: =O26 -> 67729.62 | G26: =Q26 -> 1150590.8 | H26: ==IFERROR(IF($C$18=0,B26+S26+U26,B26+S26+Y26),"") -> 0 | I26: =IFERROR(IF($C$18=0,C26+T26,C26+X26),"") -> 0.043455938 | J26: =D26+Z26 -> -240000 | L26: =D8 -> 1717200000 | M26: =L26/(24*60*60)+DATE(1970,1,1) -> 45444 | N26: =L26>$D$10 -> 0 | O26: =IF(N26=0,VLOOKUP(L26,INDEX_BTCUSD_1D!$A$1:$I$5825,9),"") -> 67729.62 | P26: =IF(N26=0,VLOOKUP(L26,FX_USDMXN_1D!$A$1:$F$4815,6),"") -> 16.988 | Q26: =IFERROR(O26*P26,"") -> 1150590.8 | R26: =IFERROR(O26/O25-1,"") -> 0.16156971 | S26: =IFERROR(-IF(N26=0,-AC25,""),"") -> 50000.002 | T26: =IF($L$2=1,IFERROR((S26*$C$16)/O26,""),IFERROR((S26*$C$16)/Q26,"")) -> 0.043455938 | U26: =IFERROR(-S26*$C$16,"") -> -50000.002 | V26: =IF(N26=0,IF(R26<=$V$24,1,0),"") -> 0 | W26: =IF(N26=0,(S26*C16)+W25+Y25,"") -> 50000.002 | X26: =IF(V26=1,IF($L$2=1,IFERROR(W26/O26,""),IFERROR(W26/Q26,"")),0) -> 0 | Y26: =IF(V26=1,-W26,0) -> 0 | Z26: =IF(N26=0,Z25+AE25,"") -> -240000 | AA26: 0 | AB26: =$C$5-AA26 -> 48 | AC26: =-PMT($C$4/12,AB26,-(Z25+AE25),,0) -> 5000 | AD26: =IFERROR(CUMIPMT($C$4/12,$AB$26,$C$12,AA27,AA27,0),0) -> 0 | AE26: =AC26+AD26 -> 5000 | AI26: loan | AJ26: =$C$12 -> 240000 | AK26: =$C$12 -> 240000 | AL26: =$C$12 -> 240000 | AM26: =$C$12 -> 240000
A27: =M27 -> 45474.437 | B27: =H26 -> 0 | C27: =I26 -> 0.043455938 | D27: =J26 -> -240000 | E27: =P27 -> 18.3516 | F27: =O27 -> 62867.66 | G27: =Q27 -> 1153722.1 | H27: ==IFERROR(IF($C$18=0,B27+S27+U27,B27+S27+Y27),"") -> 4000 | I27: =IFERROR(IF($C$18=0,C27+T27,C27+X27),"") -> 0.044322698 | J27: =Z27 -> -235000 | L27: =L26+2629743 -> 1719829743 | M27: =L27/(24*60*60)+DATE(1970,1,1) -> 45474.437 | N27: =L27>$D$10 -> 0 | O27: =IF(N27=0,VLOOKUP(L27,INDEX_BTCUSD_1D!$A$1:$I$5825,9),"") -> 62867.66 | P27: =IF(N27=0,VLOOKUP(L27,FX_USDMXN_1D!$A$1:$F$4815,6),"") -> 18.3516 | Q27: =IFERROR(O27*P27,"") -> 1153722.1 | R27: =IFERROR(O27/O26-1,"") -> -0.071784841 | S27: =IFERROR(-IF(N27=0,-AC26,""),"") -> 5000 | T27: =IF($L$2=1,IFERROR((S27*$C$17)/O27,""),IFERROR((S27*$C$17)/Q27,"")) -> 0.00086675981 | U27: =IFERROR(-S27*$C$17,"") -> -999.99999 | V27: =IF(N27=0,IF(R27<=$V$24,1,0),"") -> 1 | W27: =IF(N27=0,(S27*$C$17)+W26+Y26,"") -> 51000.002 | X27: =IF(V27=1,IF($L$2=1,IFERROR(W27/O27,""),IFERROR(W27/Q27,"")),0) -> 0.044204752 | Y27: =IF(V27=1,-W27,0) -> -51000.002 | Z27: =IF(N27=0,Z26+AE26,"") -> -235000 | AA27: =AA26+1 -> 1 | AB27: =$AB$26-AA27 -> 47 | AC27: =AC26 -> 5000 | AD27: =IFERROR(CUMIPMT($C$4/12,$AB$26,$C$12,AA28,AA28,0),0) -> 0 | AE27: =AC27+AD27 -> 5000 | AI27: annual rate | AJ27: =$C$4 -> 0 | AK27: =$C$4 -> 0 | AL27: =$C$4 -> 0 | AM27: =$C$4 -> 0
A28: =M28 -> 45504.874 | B28: =H27 -> 4000 | C28: =I27 -> 0.044322698 | D28: =J27 -> -235000 | E28: =P28 -> 18.6156 | F28: =O28 -> 64645.93 | G28: =Q28 -> 1203422.8 | H28: ==IFERROR(IF($C$18=0,B28+S28+U28,B28+S28+Y28),"") -> 7999.9999 | I28: =IFERROR(IF($C$18=0,C28+T28,C28+X28),"") -> 0.045153661 | J28: =Z28 -> -230000 | L28: =L27+2629743 -> 1722459486 | M28: =L28/(24*60*60)+DATE(1970,1,1) -> 45504.874 | N28: =L28>$D$10 -> 0 | O28: =IF(N28=0,VLOOKUP(L28,INDEX_BTCUSD_1D!$A$1:$I$5825,9),"") -> 64645.93 | P28: =IF(N28=0,VLOOKUP(L28,FX_USDMXN_1D!$A$1:$F$4815,6),"") -> 18.6156 | Q28: =IFERROR(O28*P28,"") -> 1203422.8 | R28: =IFERROR(O28/O27-1,"") -> 0.028285926 | S28: =IFERROR(-IF(N28=0,-AC27,""),"") -> 5000 | T28: =IF($L$2=1,IFERROR((S28*$C$17)/O28,""),IFERROR((S28*$C$17)/Q28,"")) -> 0.00083096316 | U28: =IFERROR(-S28*$C$17,"") -> -999.99999 | V28: =IF(N28=0,IF(R28<=$V$24,1,0),"") -> 0 | W28: =IF(N28=0,(S28*$C$17)+W27+Y27,"") -> 999.99999 | X28: =IF(V28=1,IF($L$2=1,IFERROR(W28/O28,""),IFERROR(W28/Q28,"")),0) -> 0 | Y28: =IF(V28=1,-W28,0) -> 0 | Z28: =IF(N28=0,Z27+AE27,"") -> -230000 | AA28: =AA27+1 -> 2 | AB28: =$AB$26-AA28 -> 46 | AC28: =AC27 -> 5000 | AD28: =IFERROR(CUMIPMT($C$4/12,$AB$26,$C$12,AA29,AA29,0),0) -> 0 | AE28: =AC28+AD28 -> 5000 | AI28: periods per year | AJ28: 12 | AK28: =$AJ$28 -> 12 | AL28: =$AJ$28 -> 12 | AM28: =$AJ$28 -> 12
A29: =M29 -> 45535.311 | B29: =H28 -> 7999.9999 | C29: =I28 -> 0.045153661 | D29: =J28 -> -230000 | E29: =P29 -> 19.7032 | F29: =O29 -> 59015.67 | G29: =Q29 -> 1162797.5 | H29: ==IFERROR(IF($C$18=0,B29+S29+U29,B29+S29+Y29),"") -> 12000 | I29: =IFERROR(IF($C$18=0,C29+T29,C29+X29),"") -> 0.046013656 | J29: =Z29 -> -225000 | L29: =L28+2629743 -> 1725089229 | M29: =L29/(24*60*60)+DATE(1970,1,1) -> 45535.311 | N29: =L29>$D$10 -> 0 | O29: =IF(N29=0,VLOOKUP(L29,INDEX_BTCUSD_1D!$A$1:$I$5825,9),"") -> 59015.67 | P29: =IF(N29=0,VLOOKUP(L29,FX_USDMXN_1D!$A$1:$F$4815,6),"") -> 19.7032 | Q29: =IFERROR(O29*P29,"") -> 1162797.5 | R29: =IFERROR(O29/O28-1,"") -> -0.087093805 | S29: =IFERROR(-IF(N29=0,-AC28,""),"") -> 5000 | T29: =IF($L$2=1,IFERROR((S29*$C$17)/O29,""),IFERROR((S29*$C$17)/Q29,"")) -> 0.00085999493 | U29: =IFERROR(-S29*$C$17,"") -> -999.99999 | V29: =IF(N29=0,IF(R29<=$V$24,1,0),"") -> 1 | W29: =IF(N29=0,(S29*$C$17)+W28+Y28,"") -> 2000 | X29: =IF(V29=1,IF($L$2=1,IFERROR(W29/O29,""),IFERROR(W29/Q29,"")),0) -> 0.0017199899 | Y29: =IF(V29=1,-W29,0) -> -2000 | Z29: =IF(N29=0,Z28+AE28,"") -> -225000 | AA29: =AA28+1 -> 3 | AB29: =$AB$26-AA29 -> 45 | AC29: =AC28 -> 5000 | AD29: =IFERROR(CUMIPMT($C$4/12,$AB$26,$C$12,AA30,AA30,0),0) -> 0 | AE29: =AC29+AD29 -> 5000 | AI29: rate per period | AJ29: =AJ27/AJ28 -> 0 | AK29: =AK27/AK28 -> 0 | AL29: =AL27/AL28 -> 0 | AM29: =AM27/AM28 -> 0
A30: =M30 -> 45565.747 | B30: =H29 -> 12000 | C30: =I29 -> 0.046013656 | D30: =J29 -> -225000 | E30: =P30 -> 19.68075 | F30: =O30 -> 63352.44 | G30: =Q30 -> 1246823.5 | H30: ==IFERROR(IF($C$18=0,B30+S30+U30,B30+S30+Y30),"") -> 16000 | I30: =IFERROR(IF($C$18=0,C30+T30,C30+X30),"") -> 0.046815694 | J30: =Z30 -> -220000 | L30: =L29+2629743 -> 1727718972 | M30: =L30/(24*60*60)+DATE(1970,1,1) -> 45565.747 | N30: =L30>$D$10 -> 0 | O30: =IF(N30=0,VLOOKUP(L30,INDEX_BTCUSD_1D!$A$1:$I$5825,9),"") -> 63352.44 | P30: =IF(N30=0,VLOOKUP(L30,FX_USDMXN_1D!$A$1:$F$4815,6),"") -> 19.68075 | Q30: =IFERROR(O30*P30,"") -> 1246823.5 | R30: =IFERROR(O30/O29-1,"") -> 0.073485059 | S30: =IFERROR(-IF(N30=0,-AC29,""),"") -> 5000 | T30: =IF($L$2=1,IFERROR((S30*$C$17)/O30,""),IFERROR((S30*$C$17)/Q30,"")) -> 0.00080203811 | U30: =IFERROR(-S30*$C$17,"") -> -999.99999 | V30: =IF(N30=0,IF(R30<=$V$24,1,0),"") -> 0 | W30: =IF(N30=0,(S30*$C$17)+W29+Y29,"") -> 999.99999 | X30: =IF(V30=1,IF($L$2=1,IFERROR(W30/O30,""),IFERROR(W30/Q30,"")),0) -> 0 | Y30: =IF(V30=1,-W30,0) -> 0 | Z30: =IF(N30=0,Z29+AE29,"") -> -220000 | AA30: =AA29+1 -> 4 | AB30: =$AB$26-AA30 -> 44 | AC30: =AC29 -> 5000 | AD30: =IFERROR(CUMIPMT($C$4/12,$AB$26,$C$12,AA31,AA31,0),0) -> 0 | AE30: =AC30+AD30 -> 5000 | AI30: years | AJ30: =$C$5/12 -> 4 | AK30: =$C$5/12 -> 4 | AL30: =$C$5/12 -> 4 | AM30: =$C$5/12 -> 4
A31: =M31 -> 45596.184 | B31: =H30 -> 16000 | C31: =I30 -> 0.046815694 | D31: =J30 -> -220000 | E31: =P31 -> 20.02535 | F31: =O31 -> 70244.48 | G31: =Q31 -> 1406670.3 | H31: ==IFERROR(IF($C$18=0,B31+S31+U31,B31+S31+Y31),"") -> 20000 | I31: =IFERROR(IF($C$18=0,C31+T31,C31+X31),"") -> 0.047526593 | J31: =Z31 -> -215000 | L31: =L30+2629743 -> 1730348715 | M31: =L31/(24*60*60)+DATE(1970,1,1) -> 45596.184 | N31: =L31>$D$10 -> 0 | O31: =IF(N31=0,VLOOKUP(L31,INDEX_BTCUSD_1D!$A$1:$I$5825,9),"") -> 70244.48 | P31: =IF(N31=0,VLOOKUP(L31,FX_USDMXN_1D!$A$1:$F$4815,6),"") -> 20.02535 | Q31: =IFERROR(O31*P31,"") -> 1406670.3 | R31: =IFERROR(O31/O30-1,"") -> 0.10878886 | S31: =IFERROR(-IF(N31=0,-AC30,""),"") -> 5000 | T31: =IF($L$2=1,IFERROR((S31*$C$17)/O31,""),IFERROR((S31*$C$17)/Q31,"")) -> 0.00071089863 | U31: =IFERROR(-S31*$C$17,"") -> -999.99999 | V31: =IF(N31=0,IF(R31<=$V$24,1,0),"") -> 0 | W31: =IF(N31=0,(S31*$C$17)+W30+Y30,"") -> 2000 | X31: =IF(V31=1,IF($L$2=1,IFERROR(W31/O31,""),IFERROR(W31/Q31,"")),0) -> 0 | Y31: =IF(V31=1,-W31,0) -> 0 | Z31: =IF(N31=0,Z30+AE30,"") -> -215000 | AA31: =AA30+1 -> 5 | AB31: =$AB$26-AA31 -> 43 | AC31: =AC30 -> 5000 | AD31: =IFERROR(CUMIPMT($C$4/12,$AB$26,$C$12,AA32,AA32,0),0) -> 0 | AE31: =AC31+AD31 -> 5000 | AI31: total periods | AJ31: =AJ28*AJ30 -> 48 | AK31: =AK28*AK30 -> 48 | AL31: =AL28*AL30 -> 48 | AM31: =AM28*AM30 -> 48
A32: =M32 -> 45626.621 | B32: =H31 -> 20000 | C32: =I31 -> 0.047526593 | D32: =J31 -> -215000 | E32: =P32 -> 20.36995 | F32: =O32 -> 96466.91 | G32: =Q32 -> 1965026.1 | H32: ==IFERROR(IF($C$18=0,B32+S32+U32,B32+S32+Y32),"") -> 24000 | I32: =IFERROR(IF($C$18=0,C32+T32,C32+X32),"") -> 0.048035492 | J32: =Z32 -> -210000 | L32: =L31+2629743 -> 1732978458 | M32: =L32/(24*60*60)+DATE(1970,1,1) -> 45626.621 | N32: =L32>$D$10 -> 0 | O32: =IF(N32=0,VLOOKUP(L32,INDEX_BTCUSD_1D!$A$1:$I$5825,9),"") -> 96466.91 | P32: =IF(N32=0,VLOOKUP(L32,FX_USDMXN_1D!$A$1:$F$4815,6),"") -> 20.36995 | Q32: =IFERROR(O32*P32,"") -> 1965026.1 | R32: =IFERROR(O32/O31-1,"") -> 0.37330236 | S32: =IFERROR(-IF(N32=0,-AC31,""),"") -> 5000 | T32: =IF($L$2=1,IFERROR((S32*$C$17)/O32,""),IFERROR((S32*$C$17)/Q32,"")) -> 0.00050889908 | U32: =IFERROR(-S32*$C$17,"") -> -999.99999 | V32: =IF(N32=0,IF(R32<=$V$24,1,0),"") -> 0 | W32: =IF(N32=0,(S32*$C$17)+W31+Y31,"") -> 3000 | X32: =IF(V32=1,IF($L$2=1,IFERROR(W32/O32,""),IFERROR(W32/Q32,"")),0) -> 0 | Y32: =IF(V32=1,-W32,0) -> 0 | Z32: =IF(N32=0,Z31+AE31,"") -> -210000 | AA32: =AA31+1 -> 6 | AB32: =$AB$26-AA32 -> 42 | AC32: =AC31 -> 5000 | AD32: =IFERROR(CUMIPMT($C$4/12,$AB$26,$C$12,AA33,AA33,0),0) -> 0 | AE32: =AC32+AD32 -> 5000 | AI32: start period | AJ32: 1 | AK32: =AJ33+1 -> 13 | AL32: =AK33+1 -> 25 | AM32: =AL33+1 -> 37
